Workbook

Sheet KPI
A1: KPI di servizio: Puntualità e Accuratezza
A2: L'OTIF è diviso in due KPI distinti. Ogni cliente può richiederne uno, entrambi o con soglie diverse.
A4: KPI | B4: Cosa misura | C4: Fattore che lo influenza | D4: Dettaglio
A5: Puntualità (On Time) | B5: % di consegne arrivate entro la data o la fascia oraria concordata | C5: Capacità di trasporto | D5: Mezzi e autisti disponibili rispetto agli ordini
C6: Tratta | D6: Distanza e tipo di percorso: città, autostrada, valichi alpini
C7: Eventi | D7: Neve, scioperi, blocchi stradali, guasti
C8: Persone | D8: Abilità Operazioni del manager e del Direttore Operativo
C9: Tecnologia | D9: Telematica, pianificazione delle rotte
C10: Vettori esterni | D10: Affidabilità dei padroncini e dei vettori in subvezione
A11: Accuratezza (In Full) | B11: % di ordini consegnati completi e corretti: articoli e quantità giusti, senza danni | C11: Magazzinieri | D11: Morale ed esperienza
C12: Saturazione | D12: Oltre la soglia del foglio Regole gli errori aumentano
C13: Tecnologia | D13: Lettori barcode, WMS, pick-to-light, robot
C14: Persone | D14: Abilità del manager del magazzino
C15: Tipo di merce | D15: Fragile, refrigerata o a lotti è più difficile da gestire

Sheet Clienti
A1: Requisiti dei clienti
A2: Celle in blu su sfondo giallo: da modificare. Soglia vuota = KPI non richiesto. I valori "attuali" sono esempi per provare gli esiti.
A4: Cliente | B4: Settore | C4: Soglia puntualità | D4: Soglia accuratezza | E4: Perché | F4: Puntualità attuale (esempio) | G4: Accuratezza attuale (esempio) | H4: Esito puntualità | I4: Esito accuratezza | J4: Stato complessivo
A5: Esselonga | B5: GDO freschi | C5: 0.98 | D5: 0.95 | E5: Gli scaffali vuoti al mattino sono un disastro | F5: 0.975 | G5: 0.96 | H5: =IF(C5="","Non richiesto",IF(F5>=C5,"Sopra soglia",IF(F5>=C5-Regole!$B$4,"Leggermente sotto","Molto sotto"))) -> Leggermente sotto | I5: =IF(D5="","Non richiesto",IF(G5>=D5,"Sopra soglia",IF(G5>=D5-Regole!$B$4,"Leggermente sotto","Molto sotto"))) -> Sopra soglia | J5: =IF(OR(H5="Molto sotto",I5="Molto sotto"),"Rischio penali",IF(OR(H5="Leggermente sotto",I5="Leggermente sotto"),"Soddisfazione in calo","In regola")) -> Soddisfazione in calo
A6: ElettroUnieuri | B6: Elettronica di consumo | C6: 0.9 | D6: 0.99 | E6: Un frigo sbagliato o rotto costa caro | F6: 0.93 | G6: 0.955 | H6: =IF(C6="","Non richiesto",IF(F6>=C6,"Sopra soglia",IF(F6>=C6-Regole!$B$4,"Leggermente sotto","Molto sotto"))) -> Sopra soglia | I6: =IF(D6="","Non richiesto",IF(G6>=D6,"Sopra soglia",IF(G6>=D6-Regole!$B$4,"Leggermente sotto","Molto sotto"))) -> Molto sotto | J6: =IF(OR(H6="Molto sotto",I6="Molto sotto"),"Rischio penali",IF(OR(H6="Leggermente sotto",I6="Leggermente sotto"),"Soddisfazione in calo","In regola")) -> Rischio penali
A7: Pastificio Rummolo | B7: Alimentare secco | C7: 0.92 | E7: Pasta secca: conta solo che arrivi | F7: 0.95 | G7: 0.97 | H7: =IF(C7="","Non richiesto",IF(F7>=C7,"Sopra soglia",IF(F7>=C7-Regole!$B$4,"Leggermente sotto","Molto sotto"))) -> Sopra soglia | I7: =IF(D7="","Non richiesto",IF(G7>=D7,"Sopra soglia",IF(G7>=D7-Regole!$B$4,"Leggermente sotto","Molto sotto"))) -> Non richiesto | J7: =IF(OR(H7="Molto sotto",I7="Molto sotto"),"Rischio penali",IF(OR(H7="Leggermente sotto",I7="Leggermente sotto"),"Soddisfazione in calo","In regola")) -> In regola
A8: FarmaSpa | B8: Farmaceutico | C8: 0.97 | D8: 0.995 | E8: Lotti e scadenze tracciati: cliente difficilissimo | F8: 0.97 | G8: 0.99 | H8: =IF(C8="","Non richiesto",IF(F8>=C8,"Sopra soglia",IF(F8>=C8-Regole!$B$4,"Leggermente sotto","Molto sotto"))) -> Sopra soglia | I8: =IF(D8="","Non richiesto",IF(G8>=D8,"Sopra soglia",IF(G8>=D8-Regole!$B$4,"Leggermente sotto","Molto sotto"))) -> Leggermente sotto | J8: =IF(OR(H8="Molto sotto",I8="Molto sotto"),"Rischio penali",IF(OR(H8="Leggermente sotto",I8="Leggermente sotto"),"Soddisfazione in calo","In regola")) -> Soddisfazione in calo

Sheet Regole
A1: Regole dei KPI
A3: Parametro | B3: Valore | C3: Note
A4: Margine "leggermente sotto" (punti %) | B4: 0.02 | C4: Ipotesi di design: sotto la soglia fino a questo margine = "Leggermente sotto"; oltre = "Molto sotto".
A5: Saturazione oltre cui aumentano gli errori | B5: 0.85 | C5: Ipotesi di design usata per l'accuratezza (vedi foglio KPI).
A7: Esito | B7: Effetto sul cliente
A8: Sopra soglia | B8: La soddisfazione sale; possibili bonus o ampliamenti del contratto.
A9: Leggermente sotto | B9: La soddisfazione cala.
A10: Molto sotto | B10: Penali economiche; se dura più mesi, rischio di mancato rinnovo.
A11: Non richiesto | B11: Il KPI non è nel contratto: non incide sulla soddisfazione.

Sheet Personaggi
A1: Personaggi
A2: Abilità di base + modificatori dei talenti = valore finale (limitato tra 0 e 20). I talenti si scelgono dall'elenco del foglio Talenti. Celle in blu: da modificare.
A4: Nome | B4: Età | C4: Gruppo | D4: Ruolo | E4: Provincia | F4: Talento 1 | G4: Talento 2 | H4: Talento 3 | I4: Operazioni base | J4: Precisione base | K4: Negoziazione base | L4: Leadership base | M4: Amministrazione base | N4: Innovazione base | O4: Operazioni | P4: Precisione | Q4: Negoziazione | R4: Leadership | S4: Amministrazione | T4: Innovazione | U4: Tenuta allo stress | V4: Biografia
A5: Gino Bertolotti | B5: 52 | C5: CEO giocabile | D5: Titolare, ex padroncino | E5: Alessandria | F5: Un milione di km al volante | G5: Allergico al gestionale | H5: Dialetto stretto | I5: 13 | J5: 9 | K5: 7 | L5: 11 | M5: 6 | N5: 8 | O5: =MAX(0,MIN(20,I5+IFERROR(INDEX(Talenti!$B$5:$B$24,MATCH(F5,Talenti!$A$5:$A$24,0)),0)+IFERROR(INDEX(Talenti!$B$5:$B$24,MATCH(G5,Talenti!$A$5:$A$24,0)),0)+IFERROR(INDEX(Talenti!$B$5:$B$24,MATCH(H5,Talenti!$A$5:$A$24,0)),0))) -> 17 | P5: =MAX(0,MIN(20,J5+IFERROR(INDEX(Talenti!$C$5:$C$24,MATCH(F5,Talenti!$A$5:$A$24,0)),0)+IFERROR(INDEX(Talenti!$C$5:$C$24,MATCH(G5,Talenti!$A$5:$A$24,0)),0)+IFERROR(INDEX(Talenti!$C$5:$C$24,MATCH(H5,Talenti!$A$5:$A$24,0)),0))) -> 9 | Q5: =MAX(0,MIN(20,K5+IFERROR(INDEX(Talenti!$D$5:$D$24,MATCH(F5,Talenti!$A$5:$A$24,0)),0)+IFERROR(INDEX(Talenti!$D$5:$D$24,MATCH(G5,Talenti!$A$5:$A$24,0)),0)+IFERROR(INDEX(Talenti!$D$5:$D$24,MATCH(H5,Talenti!$A$5:$A$24,0)),0))) -> 5 | R5: =MAX(0,MIN(20,L5+IFERROR(INDEX(Talenti!$E$5:$E$24,MATCH(F5,Talenti!$A$5:$A$24,0)),0)+IFERROR(INDEX(Talenti!$E$5:$E$24,MATCH(G5,Talenti!$A$5:$A$24,0)),0)+IFERROR(INDEX(Talenti!$E$5:$E$24,MATCH(H5,Talenti!$A$5:$A$24,0)),0))) -> 14 | S5: =MAX(0,MIN(20,M5+IFERROR(INDEX(Talenti!$F$5:$F$24,MATCH(F5,Talenti!$A$5:$A$24,0)),0)+IFERROR(INDEX(Talenti!$F$5:$F$24,MATCH(G5,Talenti!$A$5:$A$24,0)),0)+IFERROR(INDEX(Talenti!$F$5:$F$24,MATCH(H5,Talenti!$A$5:$A$24,0)),0))) -> 6 | T5: =MAX(0,MIN(20,N5+IFERROR(INDEX(Talenti!$G$5:$G$24,MATCH(F5,Talenti!$A$5:$A$24,0)),0)+IFERROR(INDEX(Talenti!$G$5:$G$24,MATCH(G5,Talenti!$A$5:$A$24,0)),0)+IFERROR(INDEX(Talenti!$G$5:$G$24,MATCH(H5,Talenti!$A$5:$A$24,0)),0))) -> 2 | U5: =50+IFERROR(INDEX(Talenti!$H$5:$H$24,MATCH(F5,Talenti!$A$5:$A$24,0)),0)+IFERROR(INDEX(Talenti!$H$5:$H$24,MATCH(G5,Talenti!$A$5:$A$24,0)),0)+IFERROR(INDEX(Talenti!$H$5:$H$24,MATCH(H5,Talenti!$A$5:$A$24,0)),0) -> 50 | V5: Trent'anni sulle strade d'Europa, poi il capannone di Rivalta Scrivia comprato con la liquidazione e un mutuo. Conosce ogni casello dell'A7 e diffida di tutto ciò che ha una presa elettrica.
A6: Edoardo Ferretti | B6: 31 | C6: CEO giocabile | D6: Figlio del fondatore | E6: Milano | F6: Laureato in Bocconi | G6: Papà ha sempre ragione | H6: Sempre al telefono | I6: 7 | J6: 8 | K6: 10 | L6: 8 | M6: 9 | N6: 10 | O6: =MAX(0,MIN(20,I6+IFERROR(INDEX(Talenti!$B$5:$B$24,MATCH(F6,Talenti!$A$5:$A$24,0)),0)+IFERROR(INDEX(Talenti!$B$5:$B$24,MATCH(G6,Talenti!$A$5:$A$24,0)),0)+IFERROR(INDEX(Talenti!$B$5:$B$24,MATCH(H6,Talenti!$A$5:$A$24,0)),0))) -> 6 | P6: =MAX(0,MIN(20,J6+IFERROR(INDEX(Talenti!$C$5:$C$24,MATCH(F6,Talenti!$A$5:$A$24,0)),0)+IFERROR(INDEX(Talenti!$C$5:$C$24,MATCH(G6,Talenti!$A$5:$A$24,0)),0)+IFERROR(INDEX(Talenti!$C$5:$C$24,MATCH(H6,Talenti!$A$5:$A$24,0)),0))) -> 7 | Q6: =MAX(0,MIN(20,K6+IFERROR(INDEX(Talenti!$D$5:$D$24,MATCH(F6,Talenti!$A$5:$A$24,0)),0)+IFERROR(INDEX(Talenti!$D$5:$D$24,MATCH(G6,Talenti!$A$5:$A$24,0)),0)+IFERROR(INDEX(Talenti!$D$5:$D$24,MATCH(H6,Talenti!$A$5:$A$24,0)),0))) -> 13 | R6: =MAX(0,MIN(20,L6+IFERROR(INDEX(Talenti!$E$5:$E$24,MATCH(F6,Talenti!$A$5:$A$24,0)),0)+IFERROR(INDEX(Talenti!$E$5:$E$24,MATCH(G6,Talenti!$A$5:$A$24,0)),0)+IFERROR(INDEX(Talenti!$E$5:$E$24,MATCH(H6,Talenti!$A$5:$A$24,0)),0))) -> 6 | S6: =MAX(0,MIN(20,M6+IFERROR(INDEX(Talenti!$F$5:$F$24,MATCH(F6,Talenti!$A$5:$A$24,0)),0)+IFERROR(INDEX(Talenti!$F$5:$F$24,MATCH(G6,Talenti!$A$5:$A$24,0)),0)+IFERROR(INDEX(Talenti!$F$5:$F$24,MATCH(H6,Talenti!$A$5:$A$24,0)),0))) -> 12 | T6: =MAX(0,MIN(20,N6+IFERROR(INDEX(Talenti!$G$5:$G$24,MATCH(F6,Talenti!$A$5:$A$24,0)),0)+IFERROR(INDEX(Talenti!$G$5:$G$24,MATCH(G6,Talenti!$A$5:$A$24,0)),0)+IFERROR(INDEX(Talenti!$G$5:$G$24,MATCH(H6,Talenti!$A$5:$A$24,0)),0))) -> 10 | U6: =50+IFERROR(INDEX(Talenti!$H$5:$H$24,MATCH(F6,Talenti!$A$5:$A$24,0)),0)+IFERROR(INDEX(Talenti!$H$5:$H$24,MATCH(G6,Talenti!$A$5:$A$24,0)),0)+IFERROR(INDEX(Talenti!$H$5:$H$24,MATCH(H6,Talenti!$A$5:$A$24,0)),0) -> 40 | V6: Ha ereditato il magazzino di Pioltello e un padre che passa "solo per un caffè" tutti i giorni alle 8. Vuole dimostrare di valere più del cognome.
A7: Valeria Conti | B7: 44 | C7: CEO giocabile | D7: Ex manager di multinazionale | E7: Novara | F7: Parla per acronimi | G7: Stacanovista | H7: Cena col buyer | I7: 11 | J7: 10 | K7: 12 | L7: 8 | M7: 10 | N7: 9 | O7: =MAX(0,MIN(20,I7+IFERROR(INDEX(Talenti!$B$5:$B$24,MATCH(F7,Talenti!$A$5:$A$24,0)),0)+IFERROR(INDEX(Talenti!$B$5:$B$24,MATCH(G7,Talenti!$A$5:$A$24,0)),0)+IFERROR(INDEX(Talenti!$B$5:$B$24,MATCH(H7,Talenti!$A$5:$A$24,0)),0))) -> 13 | P7: =MAX(0,MIN(20,J7+IFERROR(INDEX(Talenti!$C$5:$C$24,MATCH(F7,Talenti!$A$5:$A$24,0)),0)+IFERROR(INDEX(Talenti!$C$5:$C$24,MATCH(G7,Talenti!$A$5:$A$24,0)),0)+IFERROR(INDEX(Talenti!$C$5:$C$24,MATCH(H7,Talenti!$A$5:$A$24,0)),0))) -> 10 | Q7: =MAX(0,MIN(20,K7+IFERROR(INDEX(Talenti!$D$5:$D$24,MATCH(F7,Talenti!$A$5:$A$24,0)),0)+IFERROR(INDEX(Talenti!$D$5:$D$24,MATCH(G7,Talenti!$A$5:$A$24,0)),0)+IFERROR(INDEX(Talenti!$D$5:$D$24,MATCH(H7,Talenti!$A$5:$A$24,0)),0))) -> 18 | R7: =MAX(0,MIN(20,L7+IFERROR(INDEX(Talenti!$E$5:$E$24,MATCH(F7,Talenti!$A$5:$A$24,0)),0)+IFERROR(INDEX(Talenti!$E$5:$E$24,MATCH(G7,Talenti!$A$5:$A$24,0)),0)+IFERROR(INDEX(Talenti!$E$5:$E$24,MATCH(H7,Talenti!$A$5:$A$24,0)),0))) -> 5 | S7: =MAX(0,MIN(20,M7+IFERROR(INDEX(Talenti!$F$5:$F$24,MATCH(F7,Talenti!$A$5:$A$24,0)),0)+IFERROR(INDEX(Talenti!$F$5:$F$24,MATCH(G7,Talenti!$A$5:$A$24,0)),0)+IFERROR(INDEX(Talenti!$F$5:$F$24,MATCH(H7,Talenti!$A$5:$A$24,0)),0))) -> 10 | T7: =MAX(0,MIN(20,N7+IFERROR(INDEX(Talenti!$G$5:$G$24,MATCH(F7,Talenti!$A$5:$A$24,0)),0)+IFERROR(INDEX(Talenti!$G$5:$G$24,MATCH(G7,Talenti!$A$5:$A$24,0)),0)+IFERROR(INDEX(Talenti!$G$5:$G$24,MATCH(H7,Talenti!$A$5:$A$24,0)),0))) -> 9 | U7: =50+IFERROR(INDEX(Talenti!$H$5:$H$24,MATCH(F7,Talenti!$A$5:$A$24,0)),0)+IFERROR(INDEX(Talenti!$H$5:$H$24,MATCH(G7,Talenti!$A$5:$A$24,0)),0)+IFERROR(INDEX(Talenti!$H$5:$H$24,MATCH(H7,Talenti!$A$5:$A$24,0)),0) -> 25 | V7: Quindici anni di slide e KPI in una multinazionale. Licenziata in una ristrutturazione, ha deciso di fare da sé. Dorme quattro ore a notte e lo considera un vantaggio competitivo.
A8: Marco Pellegrino | B8: 36 | C8: CEO giocabile | D8: Ingegnere gestionale | E8: Genova | F8: Excel-dipendente | G8: Parla con i robot | H8: Calma olimpica | I8: 9 | J8: 10 | K8: 5 | L8: 8 | M8: 9 | N8: 14 | O8: =MAX(0,MIN(20,I8+IFERROR(INDEX(Talenti!$B$5:$B$24,MATCH(F8,Talenti!$A$5:$A$24,0)),0)+IFERROR(INDEX(Talenti!$B$5:$B$24,MATCH(G8,Talenti!$A$5:$A$24,0)),0)+IFERROR(INDEX(Talenti!$B$5:$B$24,MATCH(H8,Talenti!$A$5:$A$24,0)),0))) -> 9 | P8: =MAX(0,MIN(20,J8+IFERROR(INDEX(Talenti!$C$5:$C$24,MATCH(F8,Talenti!$A$5:$A$24,0)),0)+IFERROR(INDEX(Talenti!$C$5:$C$24,MATCH(G8,Talenti!$A$5:$A$24,0)),0)+IFERROR(INDEX(Talenti!$C$5:$C$24,MATCH(H8,Talenti!$A$5:$A$24,0)),0))) -> 13 | Q8: =MAX(0,MIN(20,K8+IFERROR(INDEX(Talenti!$D$5:$D$24,MATCH(F8,Talenti!$A$5:$A$24,0)),0)+IFERROR(INDEX(Talenti!$D$5:$D$24,MATCH(G8,Talenti!$A$5:$A$24,0)),0)+IFERROR(INDEX(Talenti!$D$5:$D$24,MATCH(H8,Talenti!$A$5:$A$24,0)),0))) -> 5 | R8: =MAX(0,MIN(20,L8+IFERROR(INDEX(Talenti!$E$5:$E$24,MATCH(F8,Talenti!$A$5:$A$24,0)),0)+IFERROR(INDEX(Talenti!$E$5:$E$24,MATCH(G8,Talenti!$A$5:$A$24,0)),0)+IFERROR(INDEX(Talenti!$E$5:$E$24,MATCH(H8,Talenti!$A$5:$A$24,0)),0))) -> 5 | S8: =MAX(0,MIN(20,M8+IFERROR(INDEX(Talenti!$F$5:$F$24,MATCH(F8,Talenti!$A$5:$A$24,0)),0)+IFERROR(INDEX(Talenti!$F$5:$F$24,MATCH(G8,Talenti!$A$5:$A$24,0)),0)+IFERROR(INDEX(Talenti!$F$5:$F$24,MATCH(H8,Talenti!$A$5:$A$24,0)),0))) -> 11 | T8: =MAX(0,MIN(20,N8+IFERROR(INDEX(Talenti!$G$5:$G$24,MATCH(F8,Talenti!$A$5:$A$24,0)),0)+IFERROR(INDEX(Talenti!$G$5:$G$24,MATCH(G8,Talenti!$A$5:$A$24,0)),0)+IFERROR(INDEX(Talenti!$G$5:$G$24,MATCH(H8,Talenti!$A$5:$A$24,0)),0))) -> 17 | U8: =50+IFERROR(INDEX(Talenti!$H$5:$H$24,MATCH(F8,Talenti!$A$5:$A$24,0)),0)+IFERROR(INDEX(Talenti!$H$5:$H$24,MATCH(G8,Talenti!$A$5:$A$24,0)),0)+IFERROR(INDEX(Talenti!$H$5:$H$24,MATCH(H8,Talenti!$A$5:$A$24,0)),0) -> 70 | V8: Ha progettato magazzini automatici per altri, ora ne vuole uno suo. Il piccolo deposito di Voltri è il prototipo: ogni pallet ha un codice, ogni codice ha un foglio Excel.
A9: Rosa Brambati | B9: 47 | C9: Manager disponibile | D9: Manager di magazzino | E9: Lodi | F9: Ex sindacalista | G9: Mano larga | I9: 12 | J9: 11 | K9: 6 | L9: 12 | M9: 7 | N9: 6 | O9: =MAX(0,MIN(20,I9+IFERROR(INDEX(Talenti!$B$5:$B$24,MATCH(F9,Talenti!$A$5:$A$24,0)),0)+IFERROR(INDEX(Talenti!$B$5:$B$24,MATCH(G9,Talenti!$A$5:$A$24,0)),0)+IFERROR(INDEX(Talenti!$B$5:$B$24,MATCH(H9,Talenti!$A$5:$A$24,0)),0))) -> 12 | P9: =MAX(0,MIN(20,J9+IFERROR(INDEX(Talenti!$C$5:$C$24,MATCH(F9,Talenti!$A$5:$A$24,0)),0)+IFERROR(INDEX(Talenti!$C$5:$C$24,MATCH(G9,Talenti!$A$5:$A$24,0)),0)+IFERROR(INDEX(Talenti!$C$5:$C$24,MATCH(H9,Talenti!$A$5:$A$24,0)),0))) -> 11 | Q9: =MAX(0,MIN(20,K9+IFERROR(INDEX(Talenti!$D$5:$D$24,MATCH(F9,Talenti!$A$5:$A$24,0)),0)+IFERROR(INDEX(Talenti!$D$5:$D$24,MATCH(G9,Talenti!$A$5:$A$24,0)),0)+IFERROR(INDEX(Talenti!$D$5:$D$24,MATCH(H9,Talenti!$A$5:$A$24,0)),0))) -> 7 | R9: =MAX(0,MIN(20,L9+IFERROR(INDEX(Talenti!$E$5:$E$24,MATCH(F9,Talenti!$A$5:$A$24,0)),0)+IFERROR(INDEX(Talenti!$E$5:$E$24,MATCH(G9,Talenti!$A$5:$A$24,0)),0)+IFERROR(INDEX(Talenti!$E$5:$E$24,MATCH(H9,Talenti!$A$5:$A$24,0)),0))) -> 17 | S9: =MAX(0,MIN(20,M9+IFERROR(INDEX(Talenti!$F$5:$F$24,MATCH(F9,Talenti!$A$5:$A$24,0)),0)+IFERROR(INDEX(Talenti!$F$5:$F$24,MATCH(G9,Talenti!$A$5:$A$24,0)),0)+IFERROR(INDEX(Talenti!$F$5:$F$24,MATCH(H9,Talenti!$A$5:$A$24,0)),0))) -> 5 | T9: =MAX(0,MIN(20,N9+IFERROR(INDEX(Talenti!$G$5:$G$24,MATCH(F9,Talenti!$A$5:$A$24,0)),0)+IFERROR(INDEX(Talenti!$G$5:$G$24,MATCH(G9,Talenti!$A$5:$A$24,0)),0)+IFERROR(INDEX(Talenti!$G$5:$G$24,MATCH(H9,Talenti!$A$5:$A$24,0)),0))) -> 6 | U9: =50+IFERROR(INDEX(Talenti!$H$5:$H$24,MATCH(F9,Talenti!$A$5:$A$24,0)),0)+IFERROR(INDEX(Talenti!$H$5:$H$24,MATCH(G9,Talenti!$A$5:$A$24,0)),0)+IFERROR(INDEX(Talenti!$H$5:$H$24,MATCH(H9,Talenti!$A$5:$A$24,0)),0) -> 50 | V9: Ha iniziato sul muletto, ha guidato la RSU per dieci anni. I magazzinieri la seguirebbero ovunque, i commercialisti un po' meno.
A10: Salvatore "Totò" Esposito | B10: 58 | C10: Manager disponibile | D10: Capo traffico | E10: Milano | F10: Conosce tutti al bar | G10: Sempre al telefono | I10: 14 | J10: 8 | K10: 10 | L10: 9 | M10: 6 | N10: 5 | O10: =MAX(0,MIN(20,I10+IFERROR(INDEX(Talenti!$B$5:$B$24,MATCH(F10,Talenti!$A$5:$A$24,0)),0)+IFERROR(INDEX(Talenti!$B$5:$B$24,MATCH(G10,Talenti!$A$5:$A$24,0)),0)+IFERROR(INDEX(Talenti!$B$5:$B$24,MATCH(H10,Talenti!$A$5:$A$24,0)),0))) -> 14 | P10: =MAX(0,MIN(20,J10+IFERROR(INDEX(Talenti!$C$5:$C$24,MATCH(F10,Talenti!$A$5:$A$24,0)),0)+IFERROR(INDEX(Talenti!$C$5:$C$24,MATCH(G10,Talenti!$A$5:$A$24,0)),0)+IFERROR(INDEX(Talenti!$C$5:$C$24,MATCH(H10,Talenti!$A$5:$A$24,0)),0))) -> 7 | Q10: =MAX(0,MIN(20,K10+IFERROR(INDEX(Talenti!$D$5:$D$24,MATCH(F10,Talenti!$A$5:$A$24,0)),0)+IFERROR(INDEX(Talenti!$D$5:$D$24,MATCH(G10,Talenti!$A$5:$A$24,0)),0)+IFERROR(INDEX(Talenti!$D$5:$D$24,MATCH(H10,Talenti!$A$5:$A$24,0)),0))) -> 13 | R10: =MAX(0,MIN(20,L10+IFERROR(INDEX(Talenti!$E$5:$E$24,MATCH(F10,Talenti!$A$5:$A$24,0)),0)+IFERROR(INDEX(Talenti!$E$5:$E$24,MATCH(G10,Talenti!$A$5:$A$24,0)),0)+IFERROR(INDEX(Talenti!$E$5:$E$24,MATCH(H10,Talenti!$A$5:$A$24,0)),0))) -> 11 | S10: =MAX(0,MIN(20,M10+IFERROR(INDEX(Talenti!$F$5:$F$24,MATCH(F10,Talenti!$A$5:$A$24,0)),0)+IFERROR(INDEX(Talenti!$F$5:$F$24,MATCH(G10,Talenti!$A$5:$A$24,0)),0)+IFERROR(INDEX(Talenti!$F$5:$F$24,MATCH(H10,Talenti!$A$5:$A$24,0)),0))) -> 6 | T10: =MAX(0,MIN(20,N10+IFERROR(INDEX(Talenti!$G$5:$G$24,MATCH(F10,Talenti!$A$5:$A$24,0)),0)+IFERROR(INDEX(Talenti!$G$5:$G$24,MATCH(G10,Talenti!$A$5:$A$24,0)),0)+IFERROR(INDEX(Talenti!$G$5:$G$24,MATCH(H10,Talenti!$A$5:$A$24,0)),0))) -> 5 | U10: =50+IFERROR(INDEX(Talenti!$H$5:$H$24,MATCH(F10,Talenti!$A$5:$A$24,0)),0)+IFERROR(INDEX(Talenti!$H$5:$H$24,MATCH(G10,Talenti!$A$5:$A$24,0)),0)+IFERROR(INDEX(Talenti!$H$5:$H$24,MATCH(H10,Talenti!$A$5:$A$24,0)),0) -> 45 | V10: Trasferito da Napoli nel 1979, conosce ogni padroncino della provincia per nome e soprannome. Ha tre cellulari e li usa tutti.
A11: Chiara Ferraris | B11: 29 | C11: Manager disponibile | D11: Manager junior | E11: Torino | F11: Excel-dipendente | G11: Ansia da prestazione | I11: 9 | J11: 13 | K11: 7 | L11: 6 | M11: 11 | N11: 11 | O11: =MAX(0,MIN(20,I11+IFERROR(INDEX(Talenti!$B$5:$B$24,MATCH(F11,Talenti!$A$5:$A$24,0)),0)+IFERROR(INDEX(Talenti!$B$5:$B$24,MATCH(G11,Talenti!$A$5:$A$24,0)),0)+IFERROR(INDEX(Talenti!$B$5:$B$24,MATCH(H11,Talenti!$A$5:$A$24,0)),0))) -> 9 | P11: =MAX(0,MIN(20,J11+IFERROR(INDEX(Talenti!$C$5:$C$24,MATCH(F11,Talenti!$A$5:$A$24,0)),0)+IFERROR(INDEX(Talenti!$C$5:$C$24,MATCH(G11,Talenti!$A$5:$A$24,0)),0)+IFERROR(INDEX(Talenti!$C$5:$C$24,MATCH(H11,Talenti!$A$5:$A$24,0)),0))) -> 18 | Q11: =MAX(0,MIN(20,K11+IFERROR(INDEX(Talenti!$D$5:$D$24,MATCH(F11,Talenti!$A$5:$A$24,0)),0)+IFERROR(INDEX(Talenti!$D$5:$D$24,MATCH(G11,Talenti!$A$5:$A$24,0)),0)+IFERROR(INDEX(Talenti!$D$5:$D$24,MATCH(H11,Talenti!$A$5:$A$24,0)),0))) -> 7 | R11: =MAX(0,MIN(20,L11+IFERROR(INDEX(Talenti!$E$5:$E$24,MATCH(F11,Talenti!$A$5:$A$24,0)),0)+IFERROR(INDEX(Talenti!$E$5:$E$24,MATCH(G11,Talenti!$A$5:$A$24,0)),0)+IFERROR(INDEX(Talenti!$E$5:$E$24,MATCH(H11,Talenti!$A$5:$A$24,0)),0))) -> 4 | S11: =MAX(0,MIN(20,M11+IFERROR(INDEX(Talenti!$F$5:$F$24,MATCH(F11,Talenti!$A$5:$A$24,0)),0)+IFERROR(INDEX(Talenti!$F$5:$F$24,MATCH(G11,Talenti!$A$5:$A$24,0)),0)+IFERROR(INDEX(Talenti!$F$5:$F$24,MATCH(H11,Talenti!$A$5:$A$24,0)),0))) -> 13 | T11: =MAX(0,MIN(20,N11+IFERROR(INDEX(Talenti!$G$5:$G$24,MATCH(F11,Talenti!$A$5:$A$24,0)),0)+IFERROR(INDEX(Talenti!$G$5:$G$24,MATCH(G11,Talenti!$A$5:$A$24,0)),0)+IFERROR(INDEX(Talenti!$G$5:$G$24,MATCH(H11,Talenti!$A$5:$A$24,0)),0))) -> 11 | U11: =50+IFERROR(INDEX(Talenti!$H$5:$H$24,MATCH(F11,Talenti!$A$5:$A$24,0)),0)+IFERROR(INDEX(Talenti!$H$5:$H$24,MATCH(G11,Talenti!$A$5:$A$24,0)),0)+IFERROR(INDEX(Talenti!$H$5:$H$24,MATCH(H11,Talenti!$A$5:$A$24,0)),0) -> 30 | V11: Laurea al Politecnico, due stage, un master. Prepara report impeccabili, ma un ritardo di un camion le rovina la settimana.
A12: Davide Rinaldi | B12: 39 | C12: Manager disponibile | D12: Manager di magazzino | E12: Bergamo | F12: Stacanovista | G12: Braccino corto | I12: 13 | J12: 10 | K12: 7 | L12: 8 | M12: 9 | N12: 8 | O12: =MAX(0,MIN(20,I12+IFERROR(INDEX(Talenti!$B$5:$B$24,MATCH(F12,Talenti!$A$5:$A$24,0)),0)+IFERROR(INDEX(Talenti!$B$5:$B$24,MATCH(G12,Talenti!$A$5:$A$24,0)),0)+IFERROR(INDEX(Talenti!$B$5:$B$24,MATCH(H12,Talenti!$A$5:$A$24,0)),0))) -> 15 | P12: =MAX(0,MIN(20,J12+IFERROR(INDEX(Talenti!$C$5:$C$24,MATCH(F12,Talenti!$A$5:$A$24,0)),0)+IFERROR(INDEX(Talenti!$C$5:$C$24,MATCH(G12,Talenti!$A$5:$A$24,0)),0)+IFERROR(INDEX(Talenti!$C$5:$C$24,MATCH(H12,Talenti!$A$5:$A$24,0)),0))) -> 10 | Q12: =MAX(0,MIN(20,K12+IFERROR(INDEX(Talenti!$D$5:$D$24,MATCH(F12,Talenti!$A$5:$A$24,0)),0)+IFERROR(INDEX(Talenti!$D$5:$D$24,MATCH(G12,Talenti!$A$5:$A$24,0)),0)+IFERROR(INDEX(Talenti!$D$5:$D$24,MATCH(H12,Talenti!$A$5:$A$24,0)),0))) -> 7 | R12: =MAX(0,MIN(20,L12+IFERROR(INDEX(Talenti!$E$5:$E$24,MATCH(F12,Talenti!$A$5:$A$24,0)),0)+IFERROR(INDEX(Talenti!$E$5:$E$24,MATCH(G12,Talenti!$A$5:$A$24,0)),0)+IFERROR(INDEX(Talenti!$E$5:$E$24,MATCH(H12,Talenti!$A$5:$A$24,0)),0))) -> 6 | S12: =MAX(0,MIN(20,M12+IFERROR(INDEX(Talenti!$F$5:$F$24,MATCH(F12,Talenti!$A$5:$A$24,0)),0)+IFERROR(INDEX(Talenti!$F$5:$F$24,MATCH(G12,Talenti!$A$5:$A$24,0)),0)+IFERROR(INDEX(Talenti!$F$5:$F$24,MATCH(H12,Talenti!$A$5:$A$24,0)),0))) -> 12 | T12: =MAX(0,MIN(20,N12+IFERROR(INDEX(Talenti!$G$5:$G$24,MATCH(F12,Talenti!$A$5:$A$24,0)),0)+IFERROR(INDEX(Talenti!$G$5:$G$24,MATCH(G12,Talenti!$A$5:$A$24,0)),0)+IFERROR(INDEX(Talenti!$G$5:$G$24,MATCH(H12,Talenti!$A$5:$A$24,0)),0))) -> 8 | U12: =50+IFERROR(INDEX(Talenti!$H$5:$H$24,MATCH(F12,Talenti!$A$5:$A$24,0)),0)+IFERROR(INDEX(Talenti!$H$5:$H$24,MATCH(G12,Talenti!$A$5:$A$24,0)),0)+IFERROR(INDEX(Talenti!$H$5:$H$24,MATCH(H12,Talenti!$A$5:$A$24,0)),0) -> 35 | V12: Ha portato un magazzino di Orio dal 70% al 99% di accuratezza. Nessuno sa come, nessuno ha avuto un aumento.
A13: Luca Mazzoleni | B13: 33 | C13: Manager disponibile | D13: Responsabile tecnologia | E13: Brescia | F13: Parla con i robot | G13: Insonne | I13: 8 | J13: 10 | K13: 5 | L13: 6 | M13: 8 | N13: 15 | O13: =MAX(0,MIN(20,I13+IFERROR(INDEX(Talenti!$B$5:$B$24,MATCH(F13,Talenti!$A$5:$A$24,0)),0)+IFERROR(INDEX(Talenti!$B$5:$B$24,MATCH(G13,Talenti!$A$5:$A$24,0)),0)+IFERROR(INDEX(Talenti!$B$5:$B$24,MATCH(H13,Talenti!$A$5:$A$24,0)),0))) -> 6 | P13: =MAX(0,MIN(20,J13+IFERROR(INDEX(Talenti!$C$5:$C$24,MATCH(F13,Talenti!$A$5:$A$24,0)),0)+IFERROR(INDEX(Talenti!$C$5:$C$24,MATCH(G13,Talenti!$A$5:$A$24,0)),0)+IFERROR(INDEX(Talenti!$C$5:$C$24,MATCH(H13,Talenti!$A$5:$A$24,0)),0))) -> 8 | Q13: =MAX(0,MIN(20,K13+IFERROR(INDEX(Talenti!$D$5:$D$24,MATCH(F13,Talenti!$A$5:$A$24,0)),0)+IFERROR(INDEX(Talenti!$D$5:$D$24,MATCH(G13,Talenti!$A$5:$A$24,0)),0)+IFERROR(INDEX(Talenti!$D$5:$D$24,MATCH(H13,Talenti!$A$5:$A$24,0)),0))) -> 5 | R13: =MAX(0,MIN(20,L13+IFERROR(INDEX(Talenti!$E$5:$E$24,MATCH(F13,Talenti!$A$5:$A$24,0)),0)+IFERROR(INDEX(Talenti!$E$5:$E$24,MATCH(G13,Talenti!$A$5:$A$24,0)),0)+IFERROR(INDEX(Talenti!$E$5:$E$24,MATCH(H13,Talenti!$A$5:$A$24,0)),0))) -> 4 | S13: =MAX(0,MIN(20,M13+IFERROR(INDEX(Talenti!$F$5:$F$24,MATCH(F13,Talenti!$A$5:$A$24,0)),0)+IFERROR(INDEX(Talenti!$F$5:$F$24,MATCH(G13,Talenti!$A$5:$A$24,0)),0)+IFERROR(INDEX(Talenti!$F$5:$F$24,MATCH(H13,Talenti!$A$5:$A$24,0)),0))) -> 8 | T13: =MAX(0,MIN(20,N13+IFERROR(INDEX(Talenti!$G$5:$G$24,MATCH(F13,Talenti!$A$5:$A$24,0)),0)+IFERROR(INDEX(Talenti!$G$5:$G$24,MATCH(G13,Talenti!$A$5:$A$24,0)),0)+IFERROR(INDEX(Talenti!$G$5:$G$24,MATCH(H13,Talenti!$A$5:$A$24,0)),0))) -> 18 | U13: =50+IFERROR(INDEX(Talenti!$H$5:$H$24,MATCH(F13,Talenti!$A$5:$A$24,0)),0)+IFERROR(INDEX(Talenti!$H$5:$H$24,MATCH(G13,Talenti!$A$5:$A$24,0)),0)+IFERROR(INDEX(Talenti!$H$5:$H$24,MATCH(H13,Talenti!$A$5:$A$24,0)),0) -> 40 | V13: Programma di notte, installa di giorno. Chiama i robot del magazzino per nome.
A14: Franca Gallo | B14: 61 | C14: Manager disponibile | D14: Responsabile amministrazione | E14: Alessandria | F14: Calma olimpica | G14: Braccino corto | I14: 7 | J14: 13 | K14: 8 | L14: 9 | M14: 14 | N14: 4 | O14: =MAX(0,MIN(20,I14+IFERROR(INDEX(Talenti!$B$5:$B$24,MATCH(F14,Talenti!$A$5:$A$24,0)),0)+IFERROR(INDEX(Talenti!$B$5:$B$24,MATCH(G14,Talenti!$A$5:$A$24,0)),0)+IFERROR(INDEX(Talenti!$B$5:$B$24,MATCH(H14,Talenti!$A$5:$A$24,0)),0))) -> 7 | P14: =MAX(0,MIN(20,J14+IFERROR(INDEX(Talenti!$C$5:$C$24,MATCH(F14,Talenti!$A$5:$A$24,0)),0)+IFERROR(INDEX(Talenti!$C$5:$C$24,MATCH(G14,Talenti!$A$5:$A$24,0)),0)+IFERROR(INDEX(Talenti!$C$5:$C$24,MATCH(H14,Talenti!$A$5:$A$24,0)),0))) -> 13 | Q14: =MAX(0,MIN(20,K14+IFERROR(INDEX(Talenti!$D$5:$D$24,MATCH(F14,Talenti!$A$5:$A$24,0)),0)+IFERROR(INDEX(Talenti!$D$5:$D$24,MATCH(G14,Talenti!$A$5:$A$24,0)),0)+IFERROR(INDEX(Talenti!$D$5:$D$24,MATCH(H14,Talenti!$A$5:$A$24,0)),0))) -> 8 | R14: =MAX(0,MIN(20,L14+IFERROR(INDEX(Talenti!$E$5:$E$24,MATCH(F14,Talenti!$A$5:$A$24,0)),0)+IFERROR(INDEX(Talenti!$E$5:$E$24,MATCH(G14,Talenti!$A$5:$A$24,0)),0)+IFERROR(INDEX(Talenti!$E$5:$E$24,MATCH(H14,Talenti!$A$5:$A$24,0)),0))) -> 8 | S14: =MAX(0,MIN(20,M14+IFERROR(INDEX(Talenti!$F$5:$F$24,MATCH(F14,Talenti!$A$5:$A$24,0)),0)+IFERROR(INDEX(Talenti!$F$5:$F$24,MATCH(G14,Talenti!$A$5:$A$24,0)),0)+IFERROR(INDEX(Talenti!$F$5:$F$24,MATCH(H14,Talenti!$A$5:$A$24,0)),0))) -> 17 | T14: =MAX(0,MIN(20,N14+IFERROR(INDEX(Talenti!$G$5:$G$24,MATCH(F14,Talenti!$A$5:$A$24,0)),0)+IFERROR(INDEX(Talenti!$G$5:$G$24,MATCH(G14,Talenti!$A$5:$A$24,0)),0)+IFERROR(INDEX(Talenti!$G$5:$G$24,MATCH(H14,Talenti!$A$5:$A$24,0)),0))) -> 4 | U14: =50+IFERROR(INDEX(Talenti!$H$5:$H$24,MATCH(F14,Talenti!$A$5:$A$24,0)),0)+IFERROR(INDEX(Talenti!$H$5:$H$24,MATCH(G14,Talenti!$A$5:$A$24,0)),0)+IFERROR(INDEX(Talenti!$H$5:$H$24,MATCH(H14,Talenti!$A$5:$A$24,0)),0) -> 70 | V14: Ha visto passare la lira, l'euro e tre gestionali. Le fatture le controlla ancora a mano, una per una, e non sbaglia mai.
A15: Klaus Effizienz | B15: 55 | C15: CEO concorrente | D15: CEO di Logistix Global | E15: Milano | F15: Parla per acronimi | G15: Calma olimpica | I15: 15 | J15: 14 | K15: 14 | L15: 9 | M15: 15 | N15: 13 | O15: =MAX(0,MIN(20,I15+IFERROR(INDEX(Talenti!$B$5:$B$24,MATCH(F15,Talenti!$A$5:$A$24,0)),0)+IFERROR(INDEX(Talenti!$B$5:$B$24,MATCH(G15,Talenti!$A$5:$A$24,0)),0)+IFERROR(INDEX(Talenti!$B$5:$B$24,MATCH(H15,Talenti!$A$5:$A$24,0)),0))) -> 15 | P15: =MAX(0,MIN(20,J15+IFERROR(INDEX(Talenti!$C$5:$C$24,MATCH(F15,Talenti!$A$5:$A$24,0)),0)+IFERROR(INDEX(Talenti!$C$5:$C$24,MATCH(G15,Talenti!$A$5:$A$24,0)),0)+IFERROR(INDEX(Talenti!$C$5:$C$24,MATCH(H15,Talenti!$A$5:$A$24,0)),0))) -> 14 | Q15: =MAX(0,MIN(20,K15+IFERROR(INDEX(Talenti!$D$5:$D$24,MATCH(F15,Talenti!$A$5:$A$24,0)),0)+IFERROR(INDEX(Talenti!$D$5:$D$24,MATCH(G15,Talenti!$A$5:$A$24,0)),0)+IFERROR(INDEX(Talenti!$D$5:$D$24,MATCH(H15,Talenti!$A$5:$A$24,0)),0))) -> 16 | R15: =MAX(0,MIN(20,L15+IFERROR(INDEX(Talenti!$E$5:$E$24,MATCH(F15,Talenti!$A$5:$A$24,0)),0)+IFERROR(INDEX(Talenti!$E$5:$E$24,MATCH(G15,Talenti!$A$5:$A$24,0)),0)+IFERROR(INDEX(Talenti!$E$5:$E$24,MATCH(H15,Talenti!$A$5:$A$24,0)),0))) -> 7 | S15: =MAX(0,MIN(20,M15+IFERROR(INDEX(Talenti!$F$5:$F$24,MATCH(F15,Talenti!$A$5:$A$24,0)),0)+IFERROR(INDEX(Talenti!$F$5:$F$24,MATCH(G15,Talenti!$A$5:$A$24,0)),0)+IFERROR(INDEX(Talenti!$F$5:$F$24,MATCH(H15,Talenti!$A$5:$A$24,0)),0))) -> 15 | T15: =MAX(0,MIN(20,N15+IFERROR(INDEX(Talenti!$G$5:$G$24,MATCH(F15,Talenti!$A$5:$A$24,0)),0)+IFERROR(INDEX(Talenti!$G$5:$G$24,MATCH(G15,Talenti!$A$5:$A$24,0)),0)+IFERROR(INDEX(Talenti!$G$5:$G$24,MATCH(H15,Talenti!$A$5:$A$24,0)),0))) -> 13 | U15: =50+IFERROR(INDEX(Talenti!$H$5:$H$24,MATCH(F15,Talenti!$A$5:$A$24,0)),0)+IFERROR(INDEX(Talenti!$H$5:$H$24,MATCH(G15,Talenti!$A$5:$A$24,0)),0)+IFERROR(INDEX(Talenti!$H$5:$H$24,MATCH(H15,Talenti!$A$5:$A$24,0)),0) -> 70 | V15: Arrivato da Amburgo per "razionalizzare il mercato italiano". Trova la pausa caffè una perdita di efficienza.
A16: Ambrogio Brambilla | B16: 79 | C16: CEO concorrente | D16: Fondatore di F.lli Brambilla | E16: Milano | F16: Dialetto stretto | G16: Braccino corto | I16: 12 | J16: 9 | K16: 10 | L16: 13 | M16: 11 | N16: 3 | O16: =MAX(0,MIN(20,I16+IFERROR(INDEX(Talenti!$B$5:$B$24,MATCH(F16,Talenti!$A$5:$A$24,0)),0)+IFERROR(INDEX(Talenti!$B$5:$B$24,MATCH(G16,Talenti!$A$5:$A$24,0)),0)+IFERROR(INDEX(Talenti!$B$5:$B$24,MATCH(H16,Talenti!$A$5:$A$24,0)),0))) -> 12 | P16: =MAX(0,MIN(20,J16+IFERROR(INDEX(Talenti!$C$5:$C$24,MATCH(F16,Talenti!$A$5:$A$24,0)),0)+IFERROR(INDEX(Talenti!$C$5:$C$24,MATCH(G16,Talenti!$A$5:$A$24,0)),0)+IFERROR(INDEX(Talenti!$C$5:$C$24,MATCH(H16,Talenti!$A$5:$A$24,0)),0))) -> 9 | Q16: =MAX(0,MIN(20,K16+IFERROR(INDEX(Talenti!$D$5:$D$24,MATCH(F16,Talenti!$A$5:$A$24,0)),0)+IFERROR(INDEX(Talenti!$D$5:$D$24,MATCH(G16,Talenti!$A$5:$A$24,0)),0)+IFERROR(INDEX(Talenti!$D$5:$D$24,MATCH(H16,Talenti!$A$5:$A$24,0)),0))) -> 8 | R16: =MAX(0,MIN(20,L16+IFERROR(INDEX(Talenti!$E$5:$E$24,MATCH(F16,Talenti!$A$5:$A$24,0)),0)+IFERROR(INDEX(Talenti!$E$5:$E$24,MATCH(G16,Talenti!$A$5:$A$24,0)),0)+IFERROR(INDEX(Talenti!$E$5:$E$24,MATCH(H16,Talenti!$A$5:$A$24,0)),0))) -> 13 | S16: =MAX(0,MIN(20,M16+IFERROR(INDEX(Talenti!$F$5:$F$24,MATCH(F16,Talenti!$A$5:$A$24,0)),0)+IFERROR(INDEX(Talenti!$F$5:$F$24,MATCH(G16,Talenti!$A$5:$A$24,0)),0)+IFERROR(INDEX(Talenti!$F$5:$F$24,MATCH(H16,Talenti!$A$5:$A$24,0)),0))) -> 14 | T16: =MAX(0,MIN(20,N16+IFERROR(INDEX(Talenti!$G$5:$G$24,MATCH(F16,Talenti!$A$5:$A$24,0)),0)+IFERROR(INDEX(Talenti!$G$5:$G$24,MATCH(G16,Talenti!$A$5:$A$24,0)),0)+IFERROR(INDEX(Talenti!$G$5:$G$24,MATCH(H16,Talenti!$A$5:$A$24,0)),0))) -> 3 | U16: =50+IFERROR(INDEX(Talenti!$H$5:$H$24,MATCH(F16,Talenti!$A$5:$A$24,0)),0)+IFERROR(INDEX(Talenti!$H$5:$H$24,MATCH(G16,Talenti!$A$5:$A$24,0)),0)+IFERROR(INDEX(Talenti!$H$5:$H$24,MATCH(H16,Talenti!$A$5:$A$24,0)),0) -> 50 | V16: Fondò l'azienda nel 1958 con un camion e un mulo. Non ha ancora deciso a quale dei tre figli lasciarla, e i figli non si parlano.
A17: Renato Bartolazzi | B17: 63 | C17: CEO concorrente | D17: CEO del Gruppo Bartolazzi | E17: Fuori mappa | F17: Conosce tutti al bar | G17: Ha fatto il militare | I17: 14 | J17: 10 | K17: 11 | L17: 12 | M17: 10 | N17: 7 | O17: =MAX(0,MIN(20,I17+IFERROR(INDEX(Talenti!$B$5:$B$24,MATCH(F17,Talenti!$A$5:$A$24,0)),0)+IFERROR(INDEX(Talenti!$B$5:$B$24,MATCH(G17,Talenti!$A$5:$A$24,0)),0)+IFERROR(INDEX(Talenti!$B$5:$B$24,MATCH(H17,Talenti!$A$5:$A$24,0)),0))) -> 14 | P17: =MAX(0,MIN(20,J17+IFERROR(INDEX(Talenti!$C$5:$C$24,MATCH(F17,Talenti!$A$5:$A$24,0)),0)+IFERROR(INDEX(Talenti!$C$5:$C$24,MATCH(G17,Talenti!$A$5:$A$24,0)),0)+IFERROR(INDEX(Talenti!$C$5:$C$24,MATCH(H17,Talenti!$A$5:$A$24,0)),0))) -> 11 | Q17: =MAX(0,MIN(20,K17+IFERROR(INDEX(Talenti!$D$5:$D$24,MATCH(F17,Talenti!$A$5:$A$24,0)),0)+IFERROR(INDEX(Talenti!$D$5:$D$24,MATCH(G17,Talenti!$A$5:$A$24,0)),0)+IFERROR(INDEX(Talenti!$D$5:$D$24,MATCH(H17,Talenti!$A$5:$A$24,0)),0))) -> 12 | R17: =MAX(0,MIN(20,L17+IFERROR(INDEX(Talenti!$E$5:$E$24,MATCH(F17,Talenti!$A$5:$A$24,0)),0)+IFERROR(INDEX(Talenti!$E$5:$E$24,MATCH(G17,Talenti!$A$5:$A$24,0)),0)+IFERROR(INDEX(Talenti!$E$5:$E$24,MATCH(H17,Talenti!$A$5:$A$24,0)),0))) -> 17 | S17: =MAX(0,MIN(20,M17+IFERROR(INDEX(Talenti!$F$5:$F$24,MATCH(F17,Talenti!$A$5:$A$24,0)),0)+IFERROR(INDEX(Talenti!$F$5:$F$24,MATCH(G17,Talenti!$A$5:$A$24,0)),0)+IFERROR(INDEX(Talenti!$F$5:$F$24,MATCH(H17,Talenti!$A$5:$A$24,0)),0))) -> 10 | T17: =MAX(0,MIN(20,N17+IFERROR(INDEX(Talenti!$G$5:$G$24,MATCH(F17,Talenti!$A$5:$A$24,0)),0)+IFERROR(INDEX(Talenti!$G$5:$G$24,MATCH(G17,Talenti!$A$5:$A$24,0)),0)+IFERROR(INDEX(Talenti!$G$5:$G$24,MATCH(H17,Talenti!$A$5:$A$24,0)),0))) -> 7 | U17: =50+IFERROR(INDEX(Talenti!$H$5:$H$24,MATCH(F17,Talenti!$A$5:$A$24,0)),0)+IFERROR(INDEX(Talenti!$H$5:$H$24,MATCH(G17,Talenti!$A$5:$A$24,0)),0)+IFERROR(INDEX(Talenti!$H$5:$H$24,MATCH(H17,Talenti!$A$5:$A$24,0)),0) -> 55 | V17: Guida da Bologna una rete di corrieri in tutta Italia. Nel Nord-Ovest difende ogni cliente come se fosse l'ultimo.
A18: Denis Fatica | B18: 45 | C18: CEO concorrente | D18: Presidente della Cooperativa La Fatica | E18: Pavia | F18: Braccino corto | G18: Conosce tutti al bar | I18: 10 | J18: 6 | K18: 11 | L18: 7 | M18: 12 | N18: 5 | O18: =MAX(0,MIN(20,I18+IFERROR(INDEX(Talenti!$B$5:$B$24,MATCH(F18,Talenti!$A$5:$A$24,0)),0)+IFERROR(INDEX(Talenti!$B$5:$B$24,MATCH(G18,Talenti!$A$5:$A$24,0)),0)+IFERROR(INDEX(Talenti!$B$5:$B$24,MATCH(H18,Talenti!$A$5:$A$24,0)),0))) -> 10 | P18: =MAX(0,MIN(20,J18+IFERROR(INDEX(Talenti!$C$5:$C$24,MATCH(F18,Talenti!$A$5:$A$24,0)),0)+IFERROR(INDEX(Talenti!$C$5:$C$24,MATCH(G18,Talenti!$A$5:$A$24,0)),0)+IFERROR(INDEX(Talenti!$C$5:$C$24,MATCH(H18,Talenti!$A$5:$A$24,0)),0))) -> 6 | Q18: =MAX(0,MIN(20,K18+IFERROR(INDEX(Talenti!$D$5:$D$24,MATCH(F18,Talenti!$A$5:$A$24,0)),0)+IFERROR(INDEX(Talenti!$D$5:$D$24,MATCH(G18,Talenti!$A$5:$A$24,0)),0)+IFERROR(INDEX(Talenti!$D$5:$D$24,MATCH(H18,Talenti!$A$5:$A$24,0)),0))) -> 12 | R18: =MAX(0,MIN(20,L18+IFERROR(INDEX(Talenti!$E$5:$E$24,MATCH(F18,Talenti!$A$5:$A$24,0)),0)+IFERROR(INDEX(Talenti!$E$5:$E$24,MATCH(G18,Talenti!$A$5:$A$24,0)),0)+IFERROR(INDEX(Talenti!$E$5:$E$24,MATCH(H18,Talenti!$A$5:$A$24,0)),0))) -> 7 | S18: =MAX(0,MIN(20,M18+IFERROR(INDEX(Talenti!$F$5:$F$24,MATCH(F18,Talenti!$A$5:$A$24,0)),0)+IFERROR(INDEX(Talenti!$F$5:$F$24,MATCH(G18,Talenti!$A$5:$A$24,0)),0)+IFERROR(INDEX(Talenti!$F$5:$F$24,MATCH(H18,Talenti!$A$5:$A$24,0)),0))) -> 15 | T18: =MAX(0,MIN(20,N18+IFERROR(INDEX(Talenti!$G$5:$G$24,MATCH(F18,Talenti!$A$5:$A$24,0)),0)+IFERROR(INDEX(Talenti!$G$5:$G$24,MATCH(G18,Talenti!$A$5:$A$24,0)),0)+IFERROR(INDEX(Talenti!$G$5:$G$24,MATCH(H18,Talenti!$A$5:$A$24,0)),0))) -> 5 | U18: =50+IFERROR(INDEX(Talenti!$H$5:$H$24,MATCH(F18,Talenti!$A$5:$A$24,0)),0)+IFERROR(INDEX(Talenti!$H$5:$H$24,MATCH(G18,Talenti!$A$5:$A$24,0)),0)+IFERROR(INDEX(Talenti!$H$5:$H$24,MATCH(H18,Talenti!$A$5:$A$24,0)),0) -> 50 | V18: Vince le gare con i prezzi più bassi della regione. Come ci riesca è oggetto di tre indagini e di molte chiacchiere.
A19: Ludovica Sprint | B19: 27 | C19: CEO concorrente | D19: Fondatrice di Spedisci.io (dal 2012) | E19: Milano | F19: Parla con i robot | G19: Sempre al telefono | H19: Insonne | I19: 7 | J19: 8 | K19: 13 | L19: 9 | M19: 6 | N19: 16 | O19: =MAX(0,MIN(20,I19+IFERROR(INDEX(Talenti!$B$5:$B$24,MATCH(F19,Talenti!$A$5:$A$24,0)),0)+IFERROR(INDEX(Talenti!$B$5:$B$24,MATCH(G19,Talenti!$A$5:$A$24,0)),0)+IFERROR(INDEX(Talenti!$B$5:$B$24,MATCH(H19,Talenti!$A$5:$A$24,0)),0))) -> 5 | P19: =MAX(0,MIN(20,J19+IFERROR(INDEX(Talenti!$C$5:$C$24,MATCH(F19,Talenti!$A$5:$A$24,0)),0)+IFERROR(INDEX(Talenti!$C$5:$C$24,MATCH(G19,Talenti!$A$5:$A$24,0)),0)+IFERROR(INDEX(Talenti!$C$5:$C$24,MATCH(H19,Talenti!$A$5:$A$24,0)),0))) -> 5 | Q19: =MAX(0,MIN(20,K19+IFERROR(INDEX(Talenti!$D$5:$D$24,MATCH(F19,Talenti!$A$5:$A$24,0)),0)+IFERROR(INDEX(Talenti!$D$5:$D$24,MATCH(G19,Talenti!$A$5:$A$24,0)),0)+IFERROR(INDEX(Talenti!$D$5:$D$24,MATCH(H19,Talenti!$A$5:$A$24,0)),0))) -> 15 | R19: =MAX(0,MIN(20,L19+IFERROR(INDEX(Talenti!$E$5:$E$24,MATCH(F19,Talenti!$A$5:$A$24,0)),0)+IFERROR(INDEX(Talenti!$E$5:$E$24,MATCH(G19,Talenti!$A$5:$A$24,0)),0)+IFERROR(INDEX(Talenti!$E$5:$E$24,MATCH(H19,Talenti!$A$5:$A$24,0)),0))) -> 7 | S19: =MAX(0,MIN(20,M19+IFERROR(INDEX(Talenti!$F$5:$F$24,MATCH(F19,Talenti!$A$5:$A$24,0)),0)+IFERROR(INDEX(Talenti!$F$5:$F$24,MATCH(G19,Talenti!$A$5:$A$24,0)),0)+IFERROR(INDEX(Talenti!$F$5:$F$24,MATCH(H19,Talenti!$A$5:$A$24,0)),0))) -> 6 | T19: =MAX(0,MIN(20,N19+IFERROR(INDEX(Talenti!$G$5:$G$24,MATCH(F19,Talenti!$A$5:$A$24,0)),0)+IFERROR(INDEX(Talenti!$G$5:$G$24,MATCH(G19,Talenti!$A$5:$A$24,0)),0)+IFERROR(INDEX(Talenti!$G$5:$G$24,MATCH(H19,Talenti!$A$5:$A$24,0)),0))) -> 19 | U19: =50+IFERROR(INDEX(Talenti!$H$5:$H$24,MATCH(F19,Talenti!$A$5:$A$24,0)),0)+IFERROR(INDEX(Talenti!$H$5:$H$24,MATCH(G19,Talenti!$A$5:$A$24,0)),0)+IFERROR(INDEX(Talenti!$H$5:$H$24,MATCH(H19,Talenti!$A$5:$A$24,0)),0) -> 35 | V19: Ha raccolto 20 milioni dagli investitori con una presentazione di 12 slide. Promette consegne in due ore e un'app per tutto.

Sheet Talenti
A1: Talenti
A2: Modificatori sulle sei abilità (scala 0-20) e sulla tenuta allo stress. Celle in blu: da bilanciare.
A4: Talento | B4: Operazioni | C4: Precisione | D4: Negoziazione | E4: Leadership | F4: Amministrazione | G4: Innovazione | H4: Tenuta allo stress | I4: Tipo | J4: Altri effetti
A5: Un milione di km al volante | B5: 4 | C5: 0 | D5: 0 | E5: 1 | F5: 0 | G5: -2 | H5: 0 | I5: Origine | J5: Gli autisti lo rispettano: morale autisti +5
A6: Allergico al gestionale | B6: 0 | C6: 0 | D6: 0 | E6: 0 | F6: 0 | G6: -4 | H6: 0 | I6: Negativo | J6: Curva di apprendimento +50% nel suo magazzino
A7: Dialetto stretto | B7: 0 | C7: 0 | D7: -2 | E7: 2 | F7: 0 | G7: 0 | H7: 0 | I7: Misto | J7: Opinione degli operai +10, dei clienti multinazionali −10
A8: Laureato in Bocconi | B8: -1 | C8: 0 | D8: 1 | E8: 0 | F8: 3 | G8: 0 | H8: 0 | I8: Origine | J8: Accesso a eventi con banche e investitori
A9: Papà ha sempre ragione | B9: 0 | C9: 0 | D9: 0 | E9: -2 | F9: 0 | G9: 0 | H9: -5 | I9: Negativo | J9: Il fondatore interviene negli eventi
A10: Sempre al telefono | B10: 0 | C10: -1 | D10: 2 | E10: 0 | F10: 0 | G10: 0 | H10: -5 | I10: Misto | J10: Risponde ai clienti anche in ferie
A11: Parla per acronimi | B11: 0 | C11: 0 | D11: 2 | E11: -3 | F11: 0 | G11: 0 | H11: 0 | I11: Misto | J11: Bonus nelle gare dei clienti grandi
A12: Stacanovista | B12: 2 | C12: 0 | D12: 0 | E12: 0 | F12: 0 | G12: 0 | H12: -15 | I12: Misto | J12: Lo stress sale il doppio
A13: Cena col buyer | B13: 0 | C13: 0 | D13: 4 | E13: 0 | F13: 0 | G13: 0 | H13: -10 | I13: Positivo | J13: Scelte speciali negli eventi con i clienti
A14: Excel-dipendente | B14: 0 | C14: 3 | D14: 0 | E14: -2 | F14: 2 | G14: 0 | H14: 0 | I14: Misto | J14: Report KPI più precisi
A15: Parla con i robot | B15: 0 | C15: 0 | D15: 0 | E15: -2 | F15: 0 | G15: 3 | H15: 0 | I15: Misto | J15: Curva di apprendimento −30%
A16: Calma olimpica | B16: 0 | C16: 0 | D16: 0 | E16: 1 | F16: 0 | G16: 0 | H16: 20 | I16: Positivo | J16: Ignora gli eventi di panico
... A24: Tifo sfegatato | B24: 0 | C24: 0 | D24: 0 | E24: 1 | F24: 0 | G24: 0 | H24: 0 | I24: Misto | J24: Eventi speciali nei giorni del derby

Sheet Recruiting
A1: Recruiting: compensi, welfare, canali e credibilità
A2: Valori di partenza indicativi per il 2002, da bilanciare. Celle in blu su sfondo giallo: da modificare. Il resto sono formule.
A4: 1. Ruoli e stipendio di mercato (RAL di riferimento, anno 2002)
A5: Ruolo | B5: RAL di mercato (€) | C5: Costo azienda (€/anno) | D5: Disponibilità candidati (1-5) | E5: Statistica principale | F5: Note | H5: Coefficiente costo azienda
A6: Autista patente CE | B6: 23000 | C6: =B6*$H$6 -> 32660 | D6: 2 | E6: Operazioni | F6: Carenza cronica: pochi candidati, molto contesi | H6: 1.42
A7: Autista patente C (furgoni/motrici) | B7: 20000 | C7: =B7*$H$6 -> 28400 | D7: 3 | E7: Operazioni | H7: Ipotesi: contributi, TFR e oneri ≈ +42% sulla RAL
A8: Magazziniere / mulettista | B8: 18500 | C8: =B8*$H$6 -> 26270 | D8: 4 | E8: Operazioni | F8: Spesso fornito da cooperative
A9: Impiegato traffico / customer service | B9: 22000 | C9: =B9*$H$6 -> 31240 | D9: 3 | E9: Commerciale | F9: Pianifica i viaggi, parla con i clienti
A10: Capo turno magazzino | B10: 27000 | C10: =B10*$H$6 -> 38340 | D10: 3 | E10: Persone
A11: Manager di magazzino | B11: 48000 | C11: =B11*$H$6 -> 68160 | D11: 2 | E11: Operazioni/Persone | F11: Il "vassallo" che governa un magazzino
A12: Direttore (consiglio di sede) | B12: 75000 | C12: =B12*$H$6 -> 106500 | D12: 1 | E12: Dipende dal ruolo | F12: Solo tramite head hunter o promozione
A14: 2. Province del Nord-Ovest: coefficiente stipendi e bacino di candidati
A15: Provincia | B15: Coeff. stipendi | C15: Bacino candidati (1-5) | D15: Concorrenza (1-5) | E15: Polo logistico | F15: RAL autista CE in provincia (€)
A16: Milano | B16: 1.1 | C16: 5 | D16: 5 | E16: Milano Est, Pioltello | F16: =$B$6*B16 -> 25300
A17: Torino | B17: 1.03 | C17: 4 | D17: 4 | E17: Orbassano | F17: =$B$6*B17 -> 23690
A18: Genova | B18: 1.04 | C18: 3 | D18: 3 | E18: Porto, Voltri | F18: =$B$6*B18 -> 23920
A19: Bergamo | B19: 1.03 | C19: 4 | D19: 4 | E19: Orio al Serio | F19: =$B$6*B19 -> 23690
A20: Brescia | B20: 1.02 | C20: 4 | D20: 3 | E20: Brescia Est | F20: =$B$6*B20 -> 23460
A21: Novara | B21: 1 | C21: 3 | D21: 3 | E21: CIM Novara | F21: =$B$6*B21 -> 23000
A22: Lodi | B22: 1 | C22: 3 | D22: 4 | E22: Lodi, Casalpusterlengo | F22: =$B$6*B22 -> 23000
A23: Alessandria | B23: 0.97 | C23: 3 | D23: 2 | E23: Rivalta Scrivia | F23: =$B$6*B23 -> 22310
A24: Pavia | B24: 0.97 | C24: 2 | D24: 2 | E24: Mortara | F24: =$B$6*B24 -> 22310
A25: Aosta | B25: 1 | C25: 1 | D25: 1 | E25: Aosta | F25: =$B$6*B25 -> 23000
A27: 3. Voci di welfare
A28: Voce | B28: Costo per dipendente (€/mese) | C28: Punti attrattività | D28: Effetto sul morale | E28: Disponibile dal | F28: Note
A29: Buoni pasto | B29: 110 | C29: 6 | D29: +5 | E29: 2002
A30: Mensa aziendale | B30: 90 | C30: 5 | D30: +4 | E30: 2002 | F30: In più costo fisso di 1.500 €/mese per sito
A31: Assicurazione sanitaria integrativa | B31: 35 | C31: 7 | D31: +5 | E31: 2002
A32: Premio di produzione | B32: 80 | C32: 6 | D32: +6 | E32: 2002 | F32: Legato ai KPI del magazzino
A33: Orari flessibili | B33: 0 | C33: 5 | D33: +5 | E33: 2002 | F33: Costa 2% di produttività invece di denaro
A34: Formazione continua | B34: 25 | C34: 4 | D34: +3 | E34: 2002 | F34: Aumenta anche l'esperienza
A35: Navetta dalla stazione | B35: 20 | C35: 3 | D35: +2 | E35: 2002 | F35: Utile nei poli fuori città
A36: Asilo convenzionato | B36: 40 | C36: 4 | D36: +4 | E36: 2008
A37: Smart working (solo uffici) | B37: 0 | C37: 6 | D37: +6 | E37: 2020 | F37: Solo impiegati e manager
A39: 4. Canali di ricerca
A40: Canale | B40: Costo per assunzione (€) | C40: Tempo (giorni) | D40: Qualità media candidati (1-5) | E40: Ruoli | F40: Effetti collaterali
A41: Annuncio | B41: 300 | C41: 30 | D41: 2 | E41: Tutti tranne direttori | F41: Qualità molto variabile
A42: Agenzia interinale | B42: 1200 | C42: 7 | D42: 3 | E42: Autisti, magazzinieri, impiegati | F42: Contratto temporaneo, costo orario +15%
A43: Cooperativa | B43: 0 | C43: 5 | D43: 2 | E43: Magazzinieri | F43: Costo orario -10%, morale -10, rischio vertenze
A44: Passaparola | B44: 0 | C44: 20 | D44: 4 | E44: Tutti tranne direttori | F44: Funziona solo con morale aziendale sopra 60
...

Sheet Tecnologie
A1: Investimenti in tecnologia
A2: Ricerca una volta a livello aziendale, poi installazione in ogni magazzino. Effetti in punti percentuali sui KPI del magazzino. Valori di partenza da bilanciare.
A4: Parametri
A5: Innovazione del Direttore Tecnologia (0-10) | B5: 5
A6: Riduzione tempi di ricerca per punto di Innovazione | B6: 0.05
A7: Rimborso Bando Fabbrica 4.0 (dal 2017) | B7: 0.4
A8: Maggiorazione del leasing sul costo totale | B8: 0.18
A10: Ramo | B10: Tecnologia | C10: Anno di sblocco | D10: Prerequisito | E10: Costo ricerca (€) | F10: Mesi di ricerca (base) | G10: Mesi di ricerca effettivi | H10: Installazione per sito (€) | I10: Canone mensile per sito (€) | J10: Costo primo anno per sito (€) | K10: Effetto puntualità (pp) | L10: Effetto accuratezza (pp) | M10: Settimane di apprendimento | N10: Altri effetti
A11: Informatizzazione | B11: Gestionale di base | C11: 2002 | D11: — | E11: 15000 | F11: 2 | G11: =ROUND(F11*MAX(0.4,1-$B$5*$B$6),1) -> 1.5 | H11: 5000 | I11: 300 | J11: =H11*IF(C11>=2017,1-$B$7,1)+I11*12 -> 8600 | K11: 1 | L11: 1 | M11: 2
A12: Informatizzazione | B12: WMS di base | C12: 2002 | D12: Gestionale di base | E12: 40000 | F12: 4 | G12: =ROUND(F12*MAX(0.4,1-$B$5*$B$6),1) -> 3 | H12: 25000 | I12: 800 | J12: =H12*IF(C12>=2017,1-$B$7,1)+I12*12 -> 34600 | K12: 1 | L12: 3 | M12: 6 | N12: Errori di inventario dimezzati
A13: Informatizzazione | B13: EDI con i clienti | C13: 2003 | D13: Gestionale di base | E13: 30000 | F13: 3 | G13: =ROUND(F13*MAX(0.4,1-$B$5*$B$6),1) -> 2.3 | H13: 5000 | I13: 400 | J13: =H13*IF(C13>=2017,1-$B$7,1)+I13*12 -> 9800 | K13: 2 | L13: 1 | M13: 3 | N13: Richiesto da molti clienti della GDO
A14: Informatizzazione | B14: WMS avanzato multi-sito | C14: 2010 | D14: WMS di base | E14: 90000 | F14: 6 | G14: =ROUND(F14*MAX(0.4,1-$B$5*$B$6),1) -> 4.5 | H14: 40000 | I14: 1500 | J14: =H14*IF(C14>=2017,1-$B$7,1)+I14*12 -> 58000 | K14: 1 | L14: 3 | M14: 8 | N14: Sposta merce tra magazzini
A15: Magazzino | B15: Lettori barcode | C15: 2002 | D15: — | E15: 10000 | F15: 1 | G15: =ROUND(F15*MAX(0.4,1-$B$5*$B$6),1) -> 0.8 | H15: 12000 | I15: 150 | J15: =H15*IF(C15>=2017,1-$B$7,1)+I15*12 -> 13800 | K15: 0 | L15: 2 | M15: 2
A16: Magazzino | B16: Terminali in radiofrequenza | C16: 2004 | D16: Lettori barcode; WMS di base | E16: 25000 | F16: 3 | G16: =ROUND(F16*MAX(0.4,1-$B$5*$B$6),1) -> 2.3 | H16: 30000 | I16: 400 | J16: =H16*IF(C16>=2017,1-$B$7,1)+I16*12 -> 34800 | K16: 1 | L16: 2 | M16: 4
A17: Magazzino | B17: Pick-to-light | C17: 2008 | D17: Terminali in radiofrequenza | E17: 40000 | F17: 4 | G17: =ROUND(F17*MAX(0.4,1-$B$5*$B$6),1) -> 3 | H17: 80000 | I17: 600 | J17: =H17*IF(C17>=2017,1-$B$7,1)+I17*12 -> 87200 | K17: 1 | L17: 3 | M17: 4 | N17: Picking +15% più veloce
A18: Magazzino | B18: Magazzino verticale automatico | C18: 2012 | D18: WMS avanzato multi-sito | E18: 80000 | F18: 6 | G18: =ROUND(F18*MAX(0.4,1-$B$5*$B$6),1) -> 4.5 | H18: 400000 | I18: 2500 | J18: =H18*IF(C18>=2017,1-$B$7,1)+I18*12 -> 430000 | K18: 1 | L18: 2 | M18: 10 | N18: Capacità del sito +20%
A19: Magazzino | B19: Robot mobili (AMR) | C19: 2018 | D19: Magazzino verticale automatico | E19: 150000 | F19: 8 | G19: =ROUND(F19*MAX(0.4,1-$B$5*$B$6),1) -> 6 | H19: 600000 | I19: 4000 | J19: =H19*IF(C19>=2017,1-$B$7,1)+I19*12 -> 408000 | K19: 1 | L19: 2 | M19: 12 | N19: Magazzinieri necessari -30%; tensione sindacale
A20: Trasporto | B20: Telematica GPS | C20: 2004 | D20: — | E20: 20000 | F20: 2 | G20: =ROUND(F20*MAX(0.4,1-$B$5*$B$6),1) -> 1.5 | H20: 10000 | I20: 500 | J20: =H20*IF(C20>=2017,1-$B$7,1)+I20*12 -> 16000 | K20: 2 | L20: 0 | M20: 3 | N20: Mezzi visibili in tempo reale
A21: Trasporto | B21: Pianificazione delle rotte | C21: 2007 | D21: Telematica GPS | E21: 50000 | F21: 5 | G21: =ROUND(F21*MAX(0.4,1-$B$5*$B$6),1) -> 3.8 | H21: 15000 | I21: 600 | J21: =H21*IF(C21>=2017,1-$B$7,1)+I21*12 -> 22200 | K21: 3 | L21: 0 | M21: 6 | N21: Gasolio -5%
A22: Trasporto | B22: Mezzi a metano liquido (LNG) | C22: 2014 | D22: — | E22: 60000 | F22: 6 | G22: =ROUND(F22*MAX(0.4,1-$B$5*$B$6),1) -> 4.5 | H22: 50000 | I22: 300 | J22: =H22*IF(C22>=2017,1-$B$7,1)+I22*12 -> 53600 | K22: 0 | L22: 0 | M22: 2 | N22: Gasolio -20%, credibilità +3
A23: Trasporto | B23: Furgoni elettrici urbani | C23: 2020 | D23: Telematica GPS | E23: 80000 | F23: 6 | G23: =ROUND(F23*MAX(0.4,1-$B$5*$B$6),1) -> 4.5 | H23: 90000 | I23: 800 | J23: =H23*IF(C23>=2017,1-$B$7,1)+I23*12 -> 63600 | K23: 0 | L23: 0 | M23: 4 | N23: Accesso alle ZTL, credibilità +4
A24: Dati | B24: Cruscotto KPI | C24: 2006 | D24: Gestionale di base | E24: 20000 | F24: 2 | G24: =ROUND(F24*MAX(0.4,1-$B$5*$B$6),1) -> 1.5 | H24: 3000 | I24: 200 | J24: =H24*IF(C24>=2017,1-$B$7,1)+I24*12 -> 5400 | K24: 1 | L24: 1 | M24: 2 | N24: Avvisi anticipati sui clienti a rischio
A25: Dati | B25: Previsione dei volumi | C25: 2013 | D25: Cruscotto KPI; WMS avanzato multi-sito | E25: 70000 | F25: 6 | G25: =ROUND(F25*MAX(0.4,1-$B$5*$B$6),1) -> 4.5 | H25: 10000 | I25: 700 | J25: =H25*IF(C25>=2017,1-$B$7,1)+I25*12 -> 18400 | K25: 2 | L25: 1 | M25: 6 | N25: Meno straordinari nei picchi
A26: Dati | B26: Ottimizzazione con IA | C26: 2022 | D26: Previsione dei volumi; Pianificazione delle rotte | E26: 200000 | F26: 9 | G26: =ROUND(F26*MAX(0.4,1-$B$5*$B$6),1) -> 6.8 | H26: 30000 | I26: 2000 | J26: =H26*IF(C26>=2017,1-$B$7,1)+I26*12 -> 42000 | K26: 3 | L26: 2 | M26: 10
A27: Persone e sicurezza | B27: Formazione strutturata | C27: 2002 | D27: — | E27: 8000 | F27: 1 | G27: =ROUND(F27*MAX(0.4,1-$B$5*$B$6),1) -> 0.8 | H27: 4000 | I27: 250 | J27: =H27*IF(C27>=2017,1-$B$7,1)+I27*12 -> 7000 | K27: 0 | L27: 1 | M27: 1 | N27: Morale +3, incidenti -20%
A28: Persone e sicurezza | B28: Sistemi anti-collisione muletti | C28: 2010 | D28: Formazione strutturata | E28: 15000 | F28: 2 | G28: =ROUND(F28*MAX(0.4,1-$B$5*$B$6),1) -> 1.5 | H28: 25000 | I28: 150 | J28: =H28*IF(C28>=2017,1-$B$7,1)+I28*12 -> 26800 | K28: 0 | L28: 1 | M28: 2 | N28: Incidenti -40%
A29: Persone e sicurezza | B29: Esoscheletri | C29: 2019 | D29: Sistemi anti-collisione muletti | E29: 40000 | F29: 4 | G29: =ROUND(F29*MAX(0.4,1-$B$5*$B$6),1) -> 3 | H29: 35000 | I29: 300 | J29: =H29*IF(C29>=2017,1-$B$7,1)+I29*12 -> 24600 | K29: 0 | L29: 1 | M29: 4 | N29: Assenze per infortunio -25%, morale +3
A31: Note
A32: Durante le settimane di apprendimento il magazzino perde metà dell'effetto finale invece di guadagnarlo; formazione e morale alto le accorciano.
A33: Costo primo anno per sito = installazione (ridotta del rimborso del bando per le tecnologie dal 2017) + 12 canoni.
A34: Mesi di ricerca effettivi = mesi base × (1 − Innovazione × riduzione per punto), mai sotto il 40% del tempo base.
A35: Con il leasing l'installazione non si paga subito ma si spalma su 36 mesi, con la maggiorazione indicata nei parametri.
A37: Esempio leasing
A38: Tecnologia | B38: Pick-to-light
A39: Installazione per sito (€) | B39: =INDEX($H$11:$H$29,MATCH(B38,$B$11:$B$29,0)) -> 80000
A40: Rata mensile leasing su 36 mesi (€) | B40: =B39*(1+$B$8)/36 -> 2622.2222
A41: Totale rate + canone per mese (€) | B41: =B40+INDEX($I$11:$I$29,MATCH(B38,$B$11:$B$29,0)) -> 3222.2222

Sheet Eventi
A1: Catalogo eventi
A2: Ogni riga è un evento. Effetti indicativi da bilanciare. "Scelta speciale" compare solo se un personaggio ha il talento o l'abilità indicati. Tono: Ironico / Serio.
A4: ID | B4: Categoria | C4: Fonte | D4: Titolo | E4: Testo | F4: Quando può accadere | G4: Dal | H4: Al | I4: Frequenza | J4: Scelta A | K4: Effetti A | L4: Scelta B | M4: Effetti B | N4: Scelta speciale | O4: Requisito | P4: Effetti speciale | Q4: Tono | R4: Evento successivo
A5: MET-01 | B5: Meteo e strade | C5: Radio Traffico Nord-Ovest | D5: Nebbia in Val Padana | E5: Visibilità sotto i 50 metri da Pavia a Brescia. Gli autisti chiedono di rallentare. | F5: Ottobre–febbraio; magazzino in Lombardia o Piemonte | G5: 2002 | H5: 2040 | I5: Comune | J5: Rallenta tutto | K5: Puntualità −6 pp per 7 giorni in Lombardia e Piemonte | L5: Si viaggia lo stesso | M5: Puntualità −2 pp; 15% di rischio incidente (−10 credibilità, mezzo fermo 30 giorni) | N5: "Conosco ogni curva" | O5: Talento: Un milione di km al volante | P5: Puntualità −1 pp, nessun rischio | Q5: Ironico
A6: MET-02 | B6: Meteo e strade | C6: Radio Traffico Nord-Ovest | D6: Neve al Traforo del Frejus | E6: Il traforo chiude per neve. Le consegne per Lione e Parigi sono ferme. | F6: Dicembre–marzo; flussi verso la Francia | G6: 2002 | H6: 2040 | I6: Comune | J6: Devia dal Monte Bianco | K6: +450 € per viaggio, puntualità −3 pp sui flussi esteri | L6: Aspetta la riapertura | M6: Puntualità −12 pp sui flussi esteri per 3 giorni | N6: Prenota il treno (autostrada ferroviaria) | O6: Innovazione ≥ 12 | P6: +200 € per viaggio, puntualità invariata | Q6: Ironico
A7: MET-03 | B7: Meteo e strade | C7: Radio Traffico Nord-Ovest | D7: Allerta rossa in Liguria | E7: Piogge fortissime: A10 e A6 a rischio chiusura, la Protezione Civile invita a non circolare. | F7: Settembre–novembre; magazzino in provincia di Genova | G7: 2002 | H7: 2040 | I7: Rara | J7: Chiudi il magazzino di Genova per 2 giorni | K7: Ricavi −2 giorni, morale +5, nessun rischio | L7: Resta aperto | M7: 30% di rischio danni al magazzino (−40.000 €) e infortuni (−8 credibilità) | Q7: Serio | R7: MET-03b Raccolta fondi per i comuni colpiti
A8: MET-04 | B8: Meteo e strade | C8: Radio Traffico Nord-Ovest | D8: Afa record | E8: 40 °C a Milano. I gruppi frigo vanno in crisi e in magazzino si respira a fatica. | F8: Luglio–agosto | G8: 2002 | H8: 2040 | I8: Comune | J8: Compra ventilatori e acqua per tutti | K8: −3.000 €, morale +5 | L8: Turni anticipati all'alba | M8: Produttività −5% per 10 giorni, morale invariato | N8: Pausa gelato offerta dal CEO | O8: Talento: Cena col buyer | P8: −800 €, morale +8, stress CEO −5 | Q8: Ironico
A9: MET-05 | B9: Meteo e strade | C9: La Gazzetta del Muletto | D9: Mucche sulla statale | E9: In Valle d'Aosta una mandria blocca un camion per tre ore. L'autista posta la foto: 40.000 condivisioni. | F9: Maggio–settembre; flussi verso Aosta | G9: 2002 | H9: 2040 | I9: Rara | J9: Pubblica la foto sui canali aziendali | K9: Reputazione +3 | L9: Lascia perdere | M9: Nessun effetto | Q9: Ironico
A10: POL-01 | B10: Politica e burocrazia | C10: Il Mattinale del Ministero | D10: ZTL "Zero Camion" | E10: Il nuovo assessore vieta i furgoni sotto Euro 4 nel centro di Milano dal mese prossimo. | F10: Dal 2008; flussi verso Milano città | G10: 2008 | H10: 2040 | I10: Comune | J10: Rinnova i furgoni | K10: Costo dei nuovi mezzi; credibilità +3 | L10: Ricorso al TAR | M10: −5.000 € di avvocati; 40% di vincere e rinviare il divieto di 1 anno | N10: Una telefonata in Comune | O10: Amministrazione ≥ 14 | P10: Proroga di 6 mesi, ma l'assessore si ricorderà di te | Q10: Ironico | R10: POL-01b L'assessore chiede un favore
A11: POL-02 | B11: Politica e burocrazia | C11: Il Mattinale del Ministero | D11: Decreto Semplificazione | E11: Un decreto di 340 pagine semplifica le pratiche di trasporto. Nessuno ha capito cosa cambi. | F11: Una volta ogni 2-3 anni | G11: 2002 | H11: 2040 | I11: Comune | J11: Studiatelo con calma | K11: Amministrazione rallentata per 30 giorni (costi +3%) | L11: Assumi un consulente | M11: −6.000 €, nessun rallentamento | N11: "L'ho già letto stanotte" | O11: Talento: Excel-dipendente | P11: Nessun rallentamento, stress CEO +5 | Q11: Ironico
A12: POL-03 | B12: Politica e burocrazia | C12: Il Sole 24 Pallet | D12: Sciopero nazionale degli autotrasportatori | E12: Le associazioni di categoria fermano i camion per 5 giorni contro il caro gasolio. | F12: Prezzo del gasolio in forte aumento | G12: 2002 | H12: 2040 | I12: Rara | J12: Aderisci | K12: Puntualità −20 pp per 5 giorni, morale +10, credibilità +3 | L12: Lavora lo stesso | M12: Morale −8; 25% di blocchi ai caselli (mezzi fermi 2 giorni) | N12: Media tra sindacati e clienti | O12: Leadership ≥ 14 | P12: Puntualità −8 pp, morale +5 | Q12: Ironico
A13: POL-04 | B13: Politica e burocrazia | C13: Il Mattinale del Ministero | D13: Bando Fabbrica 4.0 | E13: Il bando rimborsa il 40% degli investimenti in tecnologia. La domanda è di 60 pagine. | F13: Dal 2017, una volta l'anno | G13: 2017 | H13: 2040 | I13: Comune | J13: Partecipa | K13: 3 impiegati occupati per 30 giorni; rimborso dopo 6-18 mesi | L13: Lascia perdere | M13: Nessun effetto | N13: Delegalo al Direttore Finanza | O13: Amministrazione ≥ 12 del Direttore Finanza | P13: Nessun impiegato occupato | Q13: Ironico | R13: POL-04b Il rimborso arriva (forse)
A14: POL-05 | B14: Politica e burocrazia | C14: La Gazzetta del Muletto | D14: Elezioni comunali | E14: Entrambi i candidati sindaci ti chiedono un contributo per la campagna. | F14: Ogni 5 anni nelle province con un tuo magazzino | G14: 2002 | H14: 2040 | I14: Comune | J14: Sostieni il candidato A | K14: −5.000 €; se vince, permessi più rapidi; se perde, controlli più frequenti | L14: Resta neutrale | M14: Nessun effetto | N14: Sostieni entrambi | O14: Negoziazione ≥ 15 | P14: −10.000 €, amico di chiunque vinca, 20% di scandalo (−8 reputazione) | Q14: Ironico
A15: POL-06 | B15: Politica e burocrazia | C15: Il Mattinale del Ministero | D15: Controllo dell'Ispettorato del Lavoro | E15: Gli ispettori si presentano alle 7:00 in magazzino. | F15: Più probabile se usi cooperative | G15: 2002 | H15: 2040 | I15: Comune | J15: Collabora | K15: Multa in base alle irregolarità (0-30.000 €) | L15: Chiedi un rinvio | M15: Multa +20%, credibilità −3 | N15: "Abbiamo tutto in ordine" | O15: Precisione ≥ 14 del manager del magazzino | P15: Nessuna multa, credibilità +2 | Q15: Ironico
A16: LOC-01 | B16: Vita locale | C16: Il Sole 24 Pallet | D16: Settimana della Moda | E16: A Milano arrivano buyer da tutto il mondo. I clienti della moda raddoppiano gli ordini. | F16: Febbraio e settembre; clienti del settore moda | G16: 2002 | H16: 2040 | I16: Comune | J16: Straordinari per tutti | K16: Ricavi moda ×2 per 10 giorni, morale −5 | L16: Usa i vettori esterni | M16: Ricavi moda ×2, margine −30% | Q16: Ironico
A17: LOC-02 | B17: Vita locale | C17: Radio Traffico Nord-Ovest | D17: Passa il Giro d'Italia | E17: Una tappa blocca due province per un giorno intero. | F17: Maggio | G17: 2002 | H17: 2040 | I17: Comune | J17: Sponsorizza la tappa | K17: −15.000 €, reputazione +6 | L17: Riorganizza le consegne | M17: Puntualità −5 pp per 1 giorno | Q17: Ironico
A18: LOC-03 | B18: Vita locale | C18: La Gazzetta del Muletto | D18: Derby della Mole | E18: Metà dei magazzinieri di Torino chiede il pomeriggio libero per la partita. | F18: Magazzino in provincia di Torino | G18: 2002 | H18: 2040 | I18: Comune | J18: Concedi il pomeriggio | K18: Produttività −40% per mezza giornata, morale +6 | L18: Nega il permesso | M18: Morale −8; 30% di malattie improvvise | N18: Megaschermo in magazzino | O18: Leadership ≥ 12 | P18: −1.500 €, morale +10, produttività −10% per mezza giornata | Q18: Ironico
A19: LOC-04 | B19: Vita locale | C19: La Gazzetta del Muletto | D19: Il prete benedice i camion | E19: Il parroco propone la benedizione annuale della flotta. | F19: Magazzini fuori dalle grandi città | G19: 2002 | H19: 2040 | I19: Rara | J19: Accetta e fai una donazione | K19: −500 €, morale +4, un autista ritira le dimissioni | L19: Rifiuta gentilmente | M19: Morale −2 tra gli autisti più anziani | Q19: Ironico
A20: LOC-05 | B20: Vita locale | C20: Il Sole 24 Pallet | D20: Olimpiadi invernali di Torino | E20: Torino ospita le Olimpiadi: servono trasporti per impianti, atleti e merci. | F20: Gennaio 2006 | G20: 2006 | H20: 2006 | I20: Datato | J20: Partecipa alla gara dei trasporti olimpici | K20: Gara speciale: contratto di 2 mesi molto redditizio | L20: Ignora | M20: Traffico +20% in provincia di Torino per 2 mesi | Q20: Ironico
A21: LOC-06 | B21: Vita locale | C21: Il Sole 24 Pallet | D21: Expo Milano | E21: Sei mesi di esposizione universale: i cantieri e poi i padiglioni chiedono logistica. | F21: 2014–2015 | G21: 2014 | H21: 2015 | I21: Datato | J21: Apri un presidio vicino a Rho | K21: Nuovo cliente temporaneo, reputazione +5 | L21: Ignora | M21: Domanda in provincia di Milano +10% per 6 mesi | Q21: Ironico
A22: PER-01 | B22: Personale | C22: La Gazzetta del Muletto | D22: Vincita al Superenalotto | E22: Un magazziniere vince 2 milioni e si licenzia sul gruppo WhatsApp aziendale. | F22: Qualsiasi momento | G22: 2002 | H22: 2040 | I22: Rara | J22: Fagli gli auguri | K22: Perdi un magazziniere esperto, morale +3 | L22: Chiedigli un investimento | M22: 30% di ottenere 100.000 € di prestito a tasso zero | Q22: Ironico
A23: PER-02 | B23: Personale | C23: La Gazzetta del Muletto | D23: Il cane del manager | E23: Il manager di Novara porta in ufficio il suo bassotto, Ragù. | F23: Qualsiasi magazzino | G23: 2002 | H23: 2040 | I23: Rara | J23: Permettilo | K23: Morale +5; 20% che qualcuno sia allergico (−3 morale amministrazione) | L23: Vietalo | M23: Opinione del manager −15 | Q23: Ironico
A24: PER-03 | B24: Personale | C24: La Gazzetta del Muletto | D24: Cena di Natale finita male | E24: Il Direttore Commerciale e il capo traffico hanno litigato sul karaoke. | F24: Dicembre | G24: 2002 | H24: 2040 | I24: Comune | J24: Organizza un chiarimento | K24: Stress CEO +3, rapporto ristabilito | L24: Lascia che si arrangino | M24: Puntualità −2 pp per 2 mesi | N24: Brindisi di riconciliazione | O24: Talento: Cena col buyer | P24: Opinione di entrambi verso il CEO +10 | Q24: Ironico
A25: PER-04 | B25: Personale | C25: La Gazzetta del Muletto | D25: L'autista influencer | E25: Un tuo autista ha 300.000 follower su TikTok con i video dalla cabina. | F25: Dal 2020 | G25: 2020 | H25: 2040 | I25: Rara | J25: Fallo testimonial | K25: Reputazione +6; 20% di video imbarazzante (−5) | L25: Chiedigli di smettere | M25: Opinione dell'autista −20, 40% che si licenzi | Q25: Ironico
A26: PER-05 | B26: Personale | C26: La Gazzetta del Muletto | D26: Furto di gasolio | E26: Di notte qualcuno ha svuotato tre serbatoi nel piazzale. | F26: Magazzini senza sorveglianza | G26: 2002 | H26: 2040 | I26: Comune | J26: Installa telecamere | K26: −8.000 €, furti futuri −80% | L26: Fidati del guardiano (74 anni) | M26: Altri furti possibili, morale +2 | Q26: Ironico
