Workbook

Sheet Tecnologie
A1: Albero | B1: Livello | C1: Tecnologia | D1: Richiede | E1: Sblocca tecnologie | F1: Sblocca policy | G1: Costo ricerca (€) | H1: Ricerca (settimane) | I1: Installazione per magazzino (€) | J1: Canone mensile per magazzino (€) | K1: Apprendimento (settimane) | L1: Puntualità | M1: Accuratezza | N1: Produttività | O1: Saturazione mezzi | P1: Morale | Q1: Attrattività | R1: Altri effetti | S1: Effetto (testo del gioco) | T1: Cos'è
A2: Logistica | B2: 1 | C2: Lettori barcode | D2: — | E2: WMS di base | F2: Doppia spunta in uscita | G2: 6000 | H2: 3 | I2: 12000 | J2: 150 | K2: 2 | M2: 1.5 | S2: Meno errori di prelievo. Sblocca la policy «Doppia spunta in uscita». | T2: Ogni collo ha la sua etichetta a barre. Il magazziniere spara il codice e il sistema controlla che sia l'articolo giusto.
A3: Logistica | B3: 1 | C3: Formazione strutturata | D3: — | E3: Sicurezza muletti | F3: Rotazione delle mansioni | G3: 3000 | H3: 3 | I3: 4000 | J3: 250 | K3: 1 | M3: 1 | N3: 0.03 | S3: Corsi sul campo nel magazzino: accuratezza +1 e produttività +3%. Sblocca la policy «Rotazione delle mansioni». | T3: Corsi veri al posto del solito «guarda come faccio io». Chi sa cosa fare sbaglia meno e lavora più tranquillo.
A4: Logistica | B4: 1 | C4: Telematica GPS | D4: — | E4: Pianificazione rotte | F4: Limite 80 all'ora per i bilici | G4: 15000 | H4: 4 | I4: 10000 | J4: 500 | K4: 3 | L4: 2 | O4: 2 | S4: Mezzi visibili in tempo reale: meno ritardi, saturazione dei mezzi +2. Sblocca la policy «Limite 80 all'ora per i bilici». | T4: Una scatoletta su ogni camion che dice dove si trova. Basta telefonate all'autista per sapere quando arriva.
A5: Logistica | B5: 2 | C5: WMS di base | D5: Lettori barcode | E5: Radiofrequenza, Magazzino verticale | F5: — | G5: 40000 | H5: 11 | I5: 25000 | J5: 800 | K5: 6 | L5: 0.5 | M5: 1.5 | S5: Il magazzino sa dove sta ogni pallet. | T5: Il programma che governa il magazzino. Sa dov'è ogni pallet e dice al personale dove metterlo e dove prenderlo.
A6: Logistica | B6: 2 | C6: Sicurezza muletti | D6: Formazione strutturata | E6: Magazzino verticale | F6: Corso sicurezza obbligatorio | G6: 12000 | H6: 4 | I6: 20000 | J6: 150 | K6: 2 | M6: 0.5 | P6: 2 | S6: Sensori anti-collisione: meno danni e infortuni. Sblocca la policy «Corso sicurezza obbligatorio». | T6: Sensori e luci blu sui muletti. Avvisano il carrellista quando qualcuno è troppo vicino.
A7: Logistica | B7: 2 | C7: Pianificazione rotte | D7: Telematica GPS | E7: Sinergia in pianificazione | F7: — | G7: 35000 | H7: 7 | I7: 15000 | J7: 600 | K7: 4 | L7: 2 | O7: 5 | R7: Gasolio −5% | S7: Percorsi ottimizzati: gasolio −5%, saturazione dei mezzi +5. | T7: Un programma calcola il giro migliore per ogni camion. Meno chilometri a vuoto, meno gasolio.
A8: Logistica | B8: 3 | C8: Radiofrequenza | D8: WMS di base | E8: Pick-to-light | F8: — | G8: 25000 | H8: 6 | I8: 30000 | J8: 400 | K8: 4 | L8: 0.5 | M8: 1 | N8: 0.1 | S8: Terminali senza carta: produttività +10%. | T8: Terminali portatili collegati al WMS. Le liste di prelievo arrivano sullo schermo, non più su carta.
A9: Logistica | B9: 3 | C9: Magazzino verticale | D9: WMS di base, Sicurezza muletti | E9: Robot mobili (AMR) | F9: — | G9: 80000 | H9: 17 | I9: 250000 | J9: 2000 | K9: 10 | M9: 0.5 | R9: Capacità +20% | S9: Scaffalature automatiche: capacità +20%. | T9: Torri automatiche che portano la merce all'operatore. Si sfrutta tutta l'altezza del capannone.
A10: Logistica | B10: 3 | C10: Sinergia in pianificazione | D10: Pianificazione rotte | E10: — | F10: — | G10: 45000 | H10: 9 | I10: 15000 | J10: 500 | K10: 6 | R10: Saturazione +4 per cliente in più (max +15) | S10: Merce di clienti diversi sullo stesso camion: saturazione dei mezzi +4 per ogni cliente oltre il primo (massimo +15), se servono gli stessi canali. | T10: I pianificatori mettono insieme la merce di clienti diversi diretta nella stessa zona. Si viaggia più pieni.
A11: Logistica | B11: 4 | C11: Pick-to-light | D11: Radiofrequenza | E11: Robot mobili (AMR) | F11: — | G11: 40000 | H11: 9 | I11: 80000 | J11: 600 | K11: 4 | L11: 0.5 | M11: 2 | N11: 0.15 | S11: Picking guidato dalle luci: produttività +15%. | T11: Una luce si accende sulla casella da cui prelevare e indica quanti pezzi prendere. Si va veloci e si sbaglia poco.
A12: Logistica | B12: 5 | C12: Robot mobili (AMR) | D12: Pick-to-light, Magazzino verticale | E12: — | F12: — | G12: 150000 | H12: 21 | I12: 300000 | J12: 3000 | K12: 12 | L12: 1 | M12: 1 | N12: 0.4 | S12: Robot che portano gli scaffali agli operatori: produttività +40%. | T12: Piccoli robot girano per il magazzino e portano gli scaffali a chi prepara gli ordini. Nessuno cammina più per chilometri.
A13: Sviluppo aziendale | B13: 1 | C13: Gestionale amministrativo | D13: — | E13: Ufficio del personale, Struttura direzionale | F13: — | G13: 15000 | H13: 4 | S13: Fatture e paghe informatizzate: costi fissi −3%, ogni impiegato regge più volume. | T13: Un unico programma per fatture, paghe e contabilità. Addio fogli Excel sparsi sulle scrivanie.
A14: Sviluppo aziendale | B14: 1 | C14: Regolamento aziendale | D14: — | E14: — | F14: Zero straordinario, Sabato obbligatorio, Telefoni nell'armadietto | G14: 8000 | H14: 3 | S14: Apre la finestra Policy e sblocca le prime tre: Zero straordinario, Sabato obbligatorio e Telefoni nell'armadietto. | T14: Un fascicolo di regole scritte e firmate, appeso in bacheca accanto alla macchinetta del caffè. Finalmente si sa chi decide cosa.
A15: Sviluppo aziendale | B15: 2 | C15: Ufficio del personale | D15: Gestionale amministrativo | E15: Piattaforma welfare | F15: Niente cooperative | G15: 20000 | H15: 6 | S15: Selezione più rapida: tempi di assunzione −20%. Sblocca la policy «Niente cooperative». | T15: Un ufficio che si occupa solo di cercare, assumere e seguire le persone.
A16: Sviluppo aziendale | B16: 2 | C16: Struttura direzionale | D16: Gestionale amministrativo | E16: Controllo di gestione | F16: — | G16: 50000 | H16: 13 | S16: Sblocca la squadra dei dirigenti: cinque direttori che guidano tutta l'azienda. | T16: L'azienda smette di essere solo il CEO e qualche fedelissimo. Arrivano i direttori, ognuno con la sua area.
A17: Sviluppo aziendale | B17: 3 | C17: Piattaforma welfare | D17: Ufficio del personale | E17: Academy aziendale | F17: — | G17: 25000 | H17: 6 | S17: Convenzioni e acquisti in blocco: benefit aziendali −30% e canone dei servizi di welfare dei magazzini −30%. | T17: Un portale con convenzioni e servizi per i dipendenti. Comprando in blocco si spende meno.
A18: Sviluppo aziendale | B18: 3 | C18: Controllo di gestione | D18: Struttura direzionale | E18: Certificazione ISO 9001 | F18: Spending review | G18: 40000 | H18: 9 | S18: Budget e analisi dei costi: costi fissi −4%. Sblocca la policy «Spending review». | T18: Budget, centri di costo e una riunione al mese sui numeri. Si scopre dove spariscono i soldi.
A19: Sviluppo aziendale | B19: 4 | C19: Academy aziendale | D19: Piattaforma welfare | E19: — | F19: — | G19: 60000 | H19: 13 | S19: Scuola interna per tutta l'azienda: apprendimento delle tecnologie −30% e attrattività +5 in tutti i magazzini (chi cerca lavoro vede che si può crescere). | T19: Una scuola interna con aule e formatori. Chi ha esperienza insegna ai nuovi.
A20: Sviluppo aziendale | B20: 4 | C20: Certificazione ISO 9001 | D20: Controllo di gestione | E20: — | F20: — | G20: 45000 | H20: 17 | S20: Accuratezza +0,5 ovunque, reputazione +5, punteggio nelle gare +3. | T20: Procedure scritte, controlli e un ente esterno che verifica. I clienti si fidano di più.
A21: Mercato | B21: 1 | C21: Ufficio commerciale | D21: — | E21: EDI con i clienti, Marketing e fiere | F21: — | G21: 15000 | H21: 4 | S21: Più gare: ne arrivano un terzo in più. | T21: Venditori che cercano nuovi clienti e seguono le gare. Non si aspetta più che squilli il telefono.
A22: Mercato | B22: 1 | C22: Catena del freddo | D22: — | E22: — | F22: — | G22: 30000 | H22: 6 | S22: Certificazione per freschi e farmaci: sblocca le gare che la richiedono. | T22: Celle refrigerate, sonde e registri delle temperature. Servono per latticini, surgelati e farmaci.
A23: Mercato | B23: 2 | C23: EDI con i clienti | D23: Ufficio commerciale | E23: Key account management, Portale clienti | F23: — | G23: 30000 | H23: 7 | S23: Ordini automatici: soddisfazione +1 al mese sopra soglia. Richiesto dalla grande distribuzione. | T23: I sistemi dell'azienda e quelli del cliente si parlano da soli. Ordini e bolle viaggiano senza fax.
A24: Mercato | B24: 2 | C24: Marketing e fiere | D24: Ufficio commerciale | E24: Logistica e-commerce | F24: — | G24: 25000 | H24: 6 | S24: Stand alle fiere di settore: reputazione +5 subito e +0,2 al mese. | T24: Stand alle fiere, brochure e qualche cena con i buyer. Il nome dell'azienda inizia a girare.
... A28: Mercato | B28: 4 | C28: Accordi quadro nazionali | D28: Key account management | E28: — | F28: — | G28: 60000 | H28: 13 | S28: Contratti nazionali con i grandi gruppi: sblocca le gare delle committenti S e A (servono anche 3 magazzini e reputazione 65). | T28: Contratti firmati con le sedi centrali dei grandi gruppi. Si gioca nel campionato nazionale.
A29: Welfare | B29: 1 | C29: Boccioni d'acqua | D29: — | E29: Servizio frutta | F29: — | G29: 2000 | H29: 3 | I29: 600 | J29: 90 | K29: 0 | P29: 1 | Q29: 1 | S29: Morale +1 e il magazzino attira un po' di più chi cerca lavoro. | T29: Erogatori di acqua fresca in reparto e in banchina. D'estate, sotto il tetto del capannone, fanno la differenza.
A30: Welfare | B30: 1 | C30: Macchinette del caffè | D30: — | E30: Sala pausa arredata | F30: — | G30: 1500 | H30: 3 | I30: 800 | J30: 120 | K30: 0 | P30: 1 | Q30: 1 | S30: Morale +1, attrattività +1. | T30: Caffè e snack a prezzo politico vicino alle baie. Il vero carburante del turno di notte.
A31: Welfare | B31: 1 | C31: Pulmini per i dipendenti | D31: — | E31: Lavoro agile, Colonnine di ricarica, Asilo aziendale | F31: — | G31: 8000 | H31: 3 | I31: 35000 | J31: 1200 | K31: 0 | L31: 0.5 | P31: 2 | Q31: 5 | S31: Morale +2, attrattività +5, puntualità +0,5. | T31: Navette che passano dai paesi vicini e dalla stazione a ogni cambio turno. Chi non ha l'auto arriva lo stesso, e in orario.
A32: Welfare | B32: 1 | C32: Spogliatoi e docce | D32: — | E32: Lavanderia delle divise | F32: — | G32: 3000 | H32: 3 | I32: 20000 | J32: 200 | K32: 0 | P32: 2 | Q32: 2 | S32: Morale +2, attrattività +2. | T32: Armadietti, docce calde e panche. A fine turno si torna a casa puliti.
A33: Welfare | B33: 1 | C33: Presidio medico | D33: — | E33: Sportello d'ascolto | F33: — | G33: 10000 | H33: 4 | I33: 15000 | J33: 1500 | K33: 0 | M33: 0.2 | P33: 2 | Q33: 3 | S33: Morale +2, attrattività +3, accuratezza +0,2. | T33: Un'infermeria con un infermiere qualche ora al giorno. Visite rapide e meno giorni di malattia.
A34: Welfare | B34: 1 | C34: Raffrescatori in reparto | D34: — | E34: — | F34: — | G34: 8000 | H34: 4 | I34: 45000 | J34: 700 | K34: 0 | N34: 0.02 | P34: 3 | Q34: 2 | S34: Morale +3, attrattività +2, produttività +2%. | T34: Grandi ventilatori ad acqua sopra le corsie. A luglio sotto il tetto di lamiera fa la differenza.
A35: Welfare | B35: 2 | C35: Servizio frutta | D35: Boccioni d'acqua | E35: Mensa aziendale | F35: — | G35: 5000 | H35: 3 | I35: 300 | J35: 250 | K35: 0 | P35: 2 | Q35: 2 | S35: Morale +2, attrattività +2. | T35: Una cassetta di frutta fresca ogni mattina in sala pausa. Mele, banane e qualche mandarino molto conteso.
A36: Welfare | B36: 2 | C36: Sala pausa arredata | D36: Macchinette del caffè | E36: — | F36: — | G36: 4000 | H36: 3 | I36: 15000 | J36: 150 | K36: 0 | P36: 2 | Q36: 2 | S36: Morale +2, attrattività +2. | T36: Divanetti, tavoli e un microonde che funziona. Dieci minuti seduti davvero, lontano dai muletti.
A37: Welfare | B37: 2 | C37: Lavoro agile | D37: Pulmini per i dipendenti | E37: — | F37: Smart working in sede | G37: 6000 | H37: 3 | S37: Sblocca la policy Smart working in sede. | T37: Portatili, VPN e un regolamento per lavorare da casa. Serve a chi in magazzino non deve toccare i pallet.
A38: Welfare | B38: 2 | C38: Lavanderia delle divise | D38: Spogliatoi e docce | E38: Palestra aziendale | F38: — | G38: 4000 | H38: 3 | I38: 3000 | J38: 400 | K38: 0 | M38: 0.2 | P38: 1 | Q38: 1 | S38: Morale +1, attrattività +1, accuratezza +0,2. | T38: Le divise si lasciano sporche e si ritrovano pulite e stirate. Si lavora in ordine e si riconosce chi è di turno.
A39: Welfare | B39: 2 | C39: Sportello d'ascolto | D39: Presidio medico | E39: Settimana corta | F39: — | G39: 12000 | H39: 4 | I39: 2000 | J39: 600 | K39: 0 | P39: 3 | Q39: 2 | S39: Morale +3, attrattività +2. | T39: Uno psicologo a disposizione una mattina a settimana. Si parla di stress, turni e problemi di casa.
A40: Welfare | B40: 2 | C40: Area cani | D40: — | E40: — | F40: — | G40: 6000 | H40: 3 | I40: 8000 | J40: 150 | K40: 0 | P40: 2 | Q40: 3 | S40: Morale +2, attrattività +3. | T40: Un recinto all'ombra dove il cane aspetta la fine del turno, con ciotole e un po' di prato. Il buonumore è contagioso.
A41: Welfare | B41: 3 | C41: Mensa aziendale | D41: Servizio frutta | E41: Orto aziendale, Asilo aziendale | F41: — | G41: 15000 | H41: 6 | I41: 60000 | J41: 2500 | K41: 0 | N41: 0.03 | P41: 4 | Q41: 4 | S41: Morale +4, attrattività +4, produttività +3%. | T41: Un pasto caldo a metà turno, cucinato sul posto. Si mangia insieme e si torna in reparto con più energia.
A42: Welfare | B42: 3 | C42: Colonnine di ricarica | D42: Pulmini per i dipendenti | E42: — | F42: — | G42: 10000 | H42: 4 | I42: 25000 | J42: 300 | K42: 0 | P42: 1 | Q42: 3 | S42: Morale +1, attrattività +3. | T42: Prese per auto e scooter elettrici nel parcheggio dei dipendenti. Si ricarica mentre si lavora.
A43: Welfare | B43: 3 | C43: Palestra aziendale | D43: Lavanderia delle divise | E43: — | F43: — | G43: 20000 | H43: 6 | I43: 40000 | J43: 900 | K43: 0 | P43: 3 | Q43: 4 | S43: Morale +3, attrattività +4. | T43: Pesi, tapis roulant e un corso di ginnastica per la schiena. Chi solleva colli tutto il giorno ringrazia.
...

Sheet Riepilogo
A1: Albero | B1: Tecnologie | C1: Costo totale ricerca (€) | D1: Settimane totali di ricerca | E1: Installazione totale per magazzino (€) | F1: Canone mensile totale per magazzino (€)
A2: Logistica | B2: =COUNTIF(Tecnologie!$A$2:$A$47,A2) -> 11 | C2: =SUMIF(Tecnologie!$A$2:$A$47,A2,Tecnologie!$G$2:$G$47) -> 451000 | D2: =SUMIF(Tecnologie!$A$2:$A$47,A2,Tecnologie!$H$2:$H$47) -> 94 | E2: =SUMIF(Tecnologie!$A$2:$A$47,A2,Tecnologie!$I$2:$I$47) -> 761000 | F2: =SUMIF(Tecnologie!$A$2:$A$47,A2,Tecnologie!$J$2:$J$47) -> 8950
A3: Sviluppo aziendale | B3: =COUNTIF(Tecnologie!$A$2:$A$47,A3) -> 8 | C3: =SUMIF(Tecnologie!$A$2:$A$47,A3,Tecnologie!$G$2:$G$47) -> 263000 | D3: =SUMIF(Tecnologie!$A$2:$A$47,A3,Tecnologie!$H$2:$H$47) -> 71 | E3: =SUMIF(Tecnologie!$A$2:$A$47,A3,Tecnologie!$I$2:$I$47) -> 0 | F3: =SUMIF(Tecnologie!$A$2:$A$47,A3,Tecnologie!$J$2:$J$47) -> 0
A4: Mercato | B4: =COUNTIF(Tecnologie!$A$2:$A$47,A4) -> 8 | C4: =SUMIF(Tecnologie!$A$2:$A$47,A4,Tecnologie!$G$2:$G$47) -> 305000 | D4: =SUMIF(Tecnologie!$A$2:$A$47,A4,Tecnologie!$H$2:$H$47) -> 66 | E4: =SUMIF(Tecnologie!$A$2:$A$47,A4,Tecnologie!$I$2:$I$47) -> 0 | F4: =SUMIF(Tecnologie!$A$2:$A$47,A4,Tecnologie!$J$2:$J$47) -> 0
A5: Welfare | B5: =COUNTIF(Tecnologie!$A$2:$A$47,A5) -> 19 | C5: =SUMIF(Tecnologie!$A$2:$A$47,A5,Tecnologie!$G$2:$G$47) -> 195500 | D5: =SUMIF(Tecnologie!$A$2:$A$47,A5,Tecnologie!$H$2:$H$47) -> 82 | E5: =SUMIF(Tecnologie!$A$2:$A$47,A5,Tecnologie!$I$2:$I$47) -> 425700 | F5: =SUMIF(Tecnologie!$A$2:$A$47,A5,Tecnologie!$J$2:$J$47) -> 13560
A6: Totale | B6: =SUM(B2:B5) -> 46 | C6: =SUM(C2:C5) -> 1214500 | D6: =SUM(D2:D5) -> 313 | E6: =SUM(E2:E5) -> 1186700 | F6: =SUM(F2:F5) -> 22510
A8: Note
A9: Dati presi da src/game.html (elenco TECH), versione attuale del gioco.
A10: Le settimane di ricerca sono quelle di base: nel gioco si accorciano con l'Innovazione.
A11: Installazione, canone e apprendimento valgono solo per Logistica e Welfare, che vanno installate in ogni magazzino.
A12: Col la tecnologia «Piattaforma welfare» il canone dei servizi Welfare scende del 30% (qui è indicato il canone pieno).
A13: Puntualità, Accuratezza, Saturazione, Morale e Attrattività sono punti; Produttività è in percentuale.
